Workbook
Name IQ_DAILY: 500000

Sheet Disclaimer
B2: Project Demeter - Financial Model
B4: DISCLAIMER This document and any other materials accompanying this document (collectively, the “Materials”) are provided on a non-binding and non-reliance basis and are for general informational and marketing purposes only. By accepting any Materials, the recipient acknowledges and agrees to the matters set out below. The Materials have been prepared by Eastdil Secured Limited (the “Advisor”) to obtain indications of interest only. The Materials do not constitute an offer or invitation to make an investment, in any form, in the opportunity discussed herein. Provision of the Materials is not intended to create any kind of contractual or fiduciary relationship between the recipient and the Sponsor or Advisor. Any offer or related transaction will only be made on the basis of the completion of the recipient’s due diligence exercise, and the negotiation and execution of full documentation. The Materials have been prepared on the basis of information obtained from Advisor’s client (the “Sponsor”) and other sources considered to be reliable. Neither the Advisor nor the Sponsor have verified information contained in the Materials or the underlying sources. This is because the Advisor and Sponsor anticipate that the intended recipient will complete their own due diligence exercise and obtain appropriate professional advice on these matters. The Advisor and the Sponsor do not undertake any duty or obligation to update the information. Neither the Advisor nor the Sponsor makes or gives any representation, warranty or guarantee, whether express or implied, that the information contained in the Materials or otherwise supplied to the recipient, at any time by or on behalf of the Advisor or the Sponsor whether in writing or not is complete or accurate or up to date, or that reasonable care has been taken in compiling, preparing or furnishing the information. The Materials provide a guide only and are not intended to be exhaustive. They should not be used as the basis of any credit analysis or other evaluation, they do not contain disclosure of any of the risks associated with the opportunity, and they are not to be construed as investment, tax or legal advice in relation to the relevant subject matter. Any opinions or estimates contained in the Materials represent the judgement of the Advisor at the time the Materials are produced and these are subject to change without notice. The Materials may contain statements, opinions, estimates, targets or projections that are forward looking and which include projections of future financial performance, anticipated growth strategies and anticipated trends and are subject to numerous risks, uncertainties and assumptions. Such statements or projections are based on current expectations and projections about future events and actual results could differ materially in light of actual events, levels of activity, performance or achievements. Estimates or forecasts in the Materials should not be interpreted as a promise or representation by the Advisor or the Sponsor as to future matters and nothing contained in the Materials should be relied upon as a representation as to future matters. Each recipient is responsible for making its own credit analysis and its own independent assessment of the relevant subject matter and such independent investigation as it considers necessary or appropriate for determining whether to participate in the relevant investment. The Materials have been prepared to obtain indications of interest only. The Materials do not constitute an offer or invitation or recommendation to buy or subscribe any securities or make an investment, in any form and in any jurisdiction, in the opportunity discussed herein. Provision of the Materials is not intended to create any kind of contractual or fiduciary relationship between the Advisor and the recipient or the Sponsor and the recipient of the Materials. Neither the Advisor nor the Sponsor accepts or assumes responsibility or liability of any kind (whether for negligence or otherwise) to any of the recipients of the Materials or to any other person for any action taken or omitted to be taken by any party in connection with or arising in any way from or in relation to the information contained in the Materials. None of the Advisor, the Sponsor or any of their or their affiliates’ respective directors, officers, employees, agents, partners or professional advisors shall be liable for any direct, indirect or consequential loss or damage suffered by any person as a result of relying on any statement contained in the Materials or any such other information. The Materials are confidential and are not to be used for any other purpose or made available to any other person without the express written consent of the Advisor. Each recipient should also be aware that some of the information may constitute material non-public information concerning Stonegate or its securities and that the use of that information may be regulated or prohibited by applicable legislation relating to insider dealing. By receipt of the Materials, each recipient undertakes not to use any of the Materials for any unlawful purpose. Each recipient should therefore take appropriate advice as to the use to which such information may lawfully be put. The Materials and any use thereof are subject to the respective non-disclosure agreement that each recipient entered into in respect of the opportunity discussed herein prior to receiving the Materials. Eastdil Secured Limited is a company incorporated under English law with its registered office at One Berkeley Street, London, W1J 8DJ. Eastdil Secured Limited is registered with the UK’s Companies House under number 12751924. Eastdil Secured © 2026. All Rights Reserved. PUB25.

Sheet Assumptions>>>

Sheet Dashboard
C3: Project Demeter
C4: Dashboard
C6: Key Inputs
C8: Valuation Assumptions | H8: Business Plan Levers
C9: Entry
C10: Entry Multiple (FY26 Outlet EBITDA) | D10: 12 | H10: Growth Capex (IM p.84)
C11: Purchasers' Costs | D11: 0.01 | H11: On / Off Toggle | I11: 1 | J11: (1 = On; 0 = Off)
H12: Target ROI | I12: 0.45
C13: Exit | H13: Growth Capex Spend per Project | I13: 40000
C14: Exit Multiple | D14: 12 | H14: # of Pubs Invested per Portfolio p.a. | I14: 42
C15: Sales Costs | D15: 0.01 | H15: Average Growth Capex Spend p.a. | I15: =-AVERAGE(Portfolio!O74:S74) -> 1482901.7
C17: Operational Assumptions | H17: Disposals (IM p.85)
H18: On / Off Toggle | I18: 1 | J18: (1 = On; 0 = Off)
C19: BCF (Growth Rate per Barrel) | H19: Disposal Multiple | I19: 13
C20: Pricing vs CPI | D20: 0.02 | H20: # of Pubs Disposed per Portfolio p.a. | I20: 16
C21: COGS Baseline | D21: 0.02 | E21: (Flat, CPI, RPI or Fixed Growth) | H21: Average Disposal Proceeds p.a. | I21: =AVERAGE(Portfolio!O75:S75) -> 23668419
C22: COGS vs Baseline | D22: 0
C23: Dist & Disp Baseline | D23: 0.02 | E23: (Flat, CPI, RPI or Fixed Growth) | H23: Surplus land (IM p.86)
H24: On / Off Toggle | I24: 1 | J24: (1 = On; 0 = Off)
C25: WSM (Absolute Growth Rate) | H25: Total Surplus land Proceeds | I25: 17500000
C26: Sales | D26: 0 | H26: Average Sale Proceeds p.a. | I26: =AVERAGE(Portfolio!O76:S76) -> 3500000
C27: Discounts | D27: 0
C28: COGS | D28: 0 | H28: Financing Assumptions
C29: Dist & Disp | D29: 0 | H29: EBITDA Multiple | I29: 7
H30: Margin | I30: 0.0475
C31: Other Assumptions | H31: Interest Method | I31: Current
C32: Maintenance Capex per Pub | D32: 8000 | H32: Type | I32: Fixed
C33: Corporate Overheads per Pub | D33: 8700 | H33: 5Y Swap | I33: 0.04026
C34: Bad Debt as % of EBITDA | D34: -0.015 | H34: Commitment Fee % | I34: 0
C35: # of Closed Pubs per Portfolio p.a. | D35: 10 | E35: ='Detailed Assumptions'!E108 -> 0.032467532 | H35: Commitment Fee Method | I35: Current
H36: UFF | I36: 0.01
H37: Amortisation | I37: 0
H38: Exit Fee | I38: 0.01
H39: Release Pricing Premium | I39: 0.15
H40: Implied LTV (%) | I40: =I29/D10 -> 0.58333333
C42: Key Outputs
C44: Valuation | H44: Returns
I45: Unlevered | J45: Levered
C46: Entry Purchase Price | D46: =-'Returns Analysis'!Q43 -> 3.460193e+08 | H46: IRR | I46: ='Returns Analysis'!I55 -> 0.14414125 | J46: ='Returns Analysis'!J55 -> 0.1913599
C47: Entry FY26 Outlet EBITDA Multiple | D47: =D$46/E47 -> 12 | E47: ='Returns Analysis'!I28 -> 28834942 | H47: Equity Multiple | I47: ='Returns Analysis'!I58 -> 1.6857874 | J47: ='Returns Analysis'!J58 -> 2.0653518
...

Sheet Detailed Assumptions
D2: Note: all figures throughout the model are in £ unless otherwise noted.
B3: X | D3: Drivers Toggles
E4: =Dashboard!I11 -> 1 | F4: =Dashboard!I18 -> 1
E5: Growth Capex | F5: Disposals | G5: Surplus Land
D6: Portfolio | E6: =IF(E$4=1,1,0) -> 1 | F6: =IF(F$4=1,1,0) -> 1 | G6: =Dashboard!$I$24 -> 1
B10: X | D10: Transaction Timing
D12: Start date | E12: 46296 | F12: Note: Should always be inputted at the beginning of the month: 01/xx/xx
D13: Exit date | E13: =EOMONTH(E12,12*5-1) -> 48121
B15: X | D15: Growth assumptions
E17: FY26E | F17: FY27E | G17: FY28E | H17: FY29E | I17: FY30E | J17: FY31E
D19: BCF Volumes
D20: Value | F20: 0 | G20: 0 | H20: 0 | I20: 0 | J20: 0
D21: Mainstream | F21: 0 | G21: 0 | H21: 0 | I21: 0 | J21: 0
D22: Premium Mainstream | F22: 0 | G22: 0 | H22: 0 | I22: 0 | J22: 0
D23: Premium | F23: 0 | G23: 0 | H23: 0 | I23: 0 | J23: 0
D25: BCF assumptions
D26: Pricing vs CPI | E26: =Dashboard!D20 -> 0.02
D27: COGS vs Baseline | E27: =Dashboard!D22 -> 0
D28: Discounts vs CPI | E28: =E26 -> 0.02
D29: Duty per Barrel | E29: 125 | F29: Note: Price per barrel is calculated on the price per barrel excl. £125 of duty. Therefore the growth rate is applied to a smaller base figure than is shown in the cashflows and growth in pricing is therefore below CPI + X% assumed here. Duty is a cost of sale which is recouped directly from the publican on a 1:1 basis.
D31: WSM assumptions
D32: Sales growth | E32: =Dashboard!D26 -> 0
D33: Discounts | E33: =Dashboard!D27 -> 0
D34: Cost of sales | E34: =Dashboard!D28 -> 0
D35: Dist & disp | E35: =Dashboard!D29 -> 0
D37: Inflation assumptions
D38: Flat Forecast | E38: Flat | F38: 0 | G38: 0 | H38: 0 | I38: 0 | J38: 0
D39: CPI forecast | E39: CPI | F39: 0.024676438 | G39: 0.023173151 | H39: 0.021449041 | I39: 0.01959863 | J39: 0.019400274
D40: RPI forecast | E40: RPI | F40: 0.035127123 | G40: 0.033197534 | H40: 0.031849589 | I40: 0.025769589 | J40: 0.021623014
D42: Inflation-driven assumptions
D43: Cost of sales / barrel | E43: =Dashboard!D21 -> 0.02 | F43: =IF(ISNUMBER($E43),$E43,INDEX(F$38:F$40,MATCH($E43,$E$38:$E$40,0))) -> 0.02 | G43: =IF(ISNUMBER($E43),$E43,INDEX(G$38:G$40,MATCH($E43,$E$38:$E$40,0))) -> 0.02 | H43: =IF(ISNUMBER($E43),$E43,INDEX(H$38:H$40,MATCH($E43,$E$38:$E$40,0))) -> 0.02 | I43: =IF(ISNUMBER($E43),$E43,INDEX(I$38:I$40,MATCH($E43,$E$38:$E$40,0))) -> 0.02 | J43: =IF(ISNUMBER($E43),$E43,INDEX(J$38:J$40,MATCH($E43,$E$38:$E$40,0))) -> 0.02
D44: Dist & disp / barrel (BCF) | E44: =Dashboard!D23 -> 0.02 | F44: =IF(ISNUMBER($E44),$E44,INDEX(F$38:F$40,MATCH($E44,$E$38:$E$40,0))) -> 0.02 | G44: =IF(ISNUMBER($E44),$E44,INDEX(G$38:G$40,MATCH($E44,$E$38:$E$40,0))) -> 0.02 | H44: =IF(ISNUMBER($E44),$E44,INDEX(H$38:H$40,MATCH($E44,$E$38:$E$40,0))) -> 0.02 | I44: =IF(ISNUMBER($E44),$E44,INDEX(I$38:I$40,MATCH($E44,$E$38:$E$40,0))) -> 0.02 | J44: =IF(ISNUMBER($E44),$E44,INDEX(J$38:J$40,MATCH($E44,$E$38:$E$40,0))) -> 0.02
D45: Tie Release Fees | E45: RPI | F45: =IF(ISNUMBER($E45),$E45,INDEX(F$38:F$40,MATCH($E45,$E$38:$E$40,0))) -> 0.035127123 | G45: =IF(ISNUMBER($E45),$E45,INDEX(G$38:G$40,MATCH($E45,$E$38:$E$40,0))) -> 0.033197534 | H45: =IF(ISNUMBER($E45),$E45,INDEX(H$38:H$40,MATCH($E45,$E$38:$E$40,0))) -> 0.031849589 | I45: =IF(ISNUMBER($E45),$E45,INDEX(I$38:I$40,MATCH($E45,$E$38:$E$40,0))) -> 0.025769589 | J45: =IF(ISNUMBER($E45),$E45,INDEX(J$38:J$40,MATCH($E45,$E$38:$E$40,0))) -> 0.021623014
D46: Other income | E46: Flat | F46: =IF(ISNUMBER($E46),$E46,INDEX(F$38:F$40,MATCH($E46,$E$38:$E$40,0))) -> 0 | G46: =IF(ISNUMBER($E46),$E46,INDEX(G$38:G$40,MATCH($E46,$E$38:$E$40,0))) -> 0 | H46: =IF(ISNUMBER($E46),$E46,INDEX(H$38:H$40,MATCH($E46,$E$38:$E$40,0))) -> 0 | I46: =IF(ISNUMBER($E46),$E46,INDEX(I$38:I$40,MATCH($E46,$E$38:$E$40,0))) -> 0 | J46: =IF(ISNUMBER($E46),$E46,INDEX(J$38:J$40,MATCH($E46,$E$38:$E$40,0))) -> 0
D47: Pub costs | E47: 0.02 | F47: =IF(ISNUMBER($E47),$E47,INDEX(F$38:F$40,MATCH($E47,$E$38:$E$40,0))) -> 0.02 | G47: =IF(ISNUMBER($E47),$E47,INDEX(G$38:G$40,MATCH($E47,$E$38:$E$40,0))) -> 0.02 | H47: =IF(ISNUMBER($E47),$E47,INDEX(H$38:H$40,MATCH($E47,$E$38:$E$40,0))) -> 0.02 | I47: =IF(ISNUMBER($E47),$E47,INDEX(I$38:I$40,MATCH($E47,$E$38:$E$40,0))) -> 0.02 | J47: =IF(ISNUMBER($E47),$E47,INDEX(J$38:J$40,MATCH($E47,$E$38:$E$40,0))) -> 0.02
D48: Maintenance capex | E48: 0.02 | F48: =IF(ISNUMBER($E48),$E48,INDEX(F$38:F$40,MATCH($E48,$E$38:$E$40,0))) -> 0.02 | G48: =IF(ISNUMBER($E48),$E48,INDEX(G$38:G$40,MATCH($E48,$E$38:$E$40,0))) -> 0.02 | H48: =IF(ISNUMBER($E48),$E48,INDEX(H$38:H$40,MATCH($E48,$E$38:$E$40,0))) -> 0.02 | I48: =IF(ISNUMBER($E48),$E48,INDEX(I$38:I$40,MATCH($E48,$E$38:$E$40,0))) -> 0.02 | J48: =IF(ISNUMBER($E48),$E48,INDEX(J$38:J$40,MATCH($E48,$E$38:$E$40,0))) -> 0.02
D49: Overheads | E49: CPI | F49: =IF(ISNUMBER($E49),$E49,INDEX(F$38:F$40,MATCH($E49,$E$38:$E$40,0))) -> 0.024676438 | G49: =IF(ISNUMBER($E49),$E49,INDEX(G$38:G$40,MATCH($E49,$E$38:$E$40,0))) -> 0.023173151 | H49: =IF(ISNUMBER($E49),$E49,INDEX(H$38:H$40,MATCH($E49,$E$38:$E$40,0))) -> 0.021449041 | I49: =IF(ISNUMBER($E49),$E49,INDEX(I$38:I$40,MATCH($E49,$E$38:$E$40,0))) -> 0.01959863 | J49: =IF(ISNUMBER($E49),$E49,INDEX(J$38:J$40,MATCH($E49,$E$38:$E$40,0))) -> 0.019400274
D50: Security costs re. closures | E50: CPI | F50: =IF(ISNUMBER($E50),$E50,INDEX(F$38:F$40,MATCH($E50,$E$38:$E$40,0))) -> 0.024676438 | G50: =IF(ISNUMBER($E50),$E50,INDEX(G$38:G$40,MATCH($E50,$E$38:$E$40,0))) -> 0.023173151 | H50: =IF(ISNUMBER($E50),$E50,INDEX(H$38:H$40,MATCH($E50,$E$38:$E$40,0))) -> 0.021449041 | I50: =IF(ISNUMBER($E50),$E50,INDEX(I$38:I$40,MATCH($E50,$E$38:$E$40,0))) -> 0.01959863 | J50: =IF(ISNUMBER($E50),$E50,INDEX(J$38:J$40,MATCH($E50,$E$38:$E$40,0))) -> 0.019400274
D52: Maintenance capex FY26F / pub / year | E52: =Dashboard!D32 -> 8000
D53: Bad debts / EBITDA | E53: =Dashboard!D34 -> -0.015
...

Sheet Outputs>>>

Sheet Returns Analysis
C2: X | E2: Assumptions
E4: Portfolio entry | P4: Sources | R4: Amount | S4: % of Total | U4: Uses | W4: Amount | X4: % of Total
E5: Entry Date | I5: =EOMONTH('Detailed Assumptions'!E12,-1) -> 46295 | P5: Day-1 Equity | R5: =-Q50 -> 1.4965335e+08 | S5: =R5/R$7 -> 0.42821782 | U5: Day-1 Purchase Price | W5: =I15 -> 3.460193e+08 | X5: =W5/W$7 -> 0.99009901
E6: Entry multiple (outlet level) | I6: =Dashboard!D10 -> 12 | P6: Day-1 Debt Drawdown | R6: =Q49 -> 1.9982615e+08 | S6: =R6/R$7 -> 0.57178218 | U6: Transaction Costs | W6: =-Q45 -> 3460193 | X6: =W6/W$7 -> 0.0099009901
E7: Purchasers' Costs | I7: =Dashboard!D11 -> 0.01 | P7: Total Day-1 Sources | R7: =SUM(R5:R6) -> 3.494795e+08 | S7: =R7/R$7 -> 1 | U7: Total Day-1 Sources | W7: =SUM(W5:W6) -> 3.494795e+08 | X7: =W7/W$7 -> 1
E9: Portfolio exit
E10: Exit multiple (outlet level) | I10: =Dashboard!D14 -> 12
E11: Exit Date | I11: ='Detailed Assumptions'!$E$13 -> 48121
E12: Sales Costs | I12: =Dashboard!D15 -> 0.01
E14: Valuation Summary
E15: Acq value | I15: =-I43 -> 3.460193e+08
E16: Outlet EBITDA multiple | I16: =I15/I28 -> 12
E17: Corporate EBITDA multiple | I17: =I15/(SUM(I28,I30)) -> 13.229393
Q18: {=INDEX(Index_Tab!$F$4:$K$4,MATCH(1,(Q$20>=Index_Tab!$F$5:$K$5)*(Q$20<=Index_Tab!$F$17:$K$17),0))} -> FY26E | R18: {=INDEX(Index_Tab!$G$4:$K$4,MATCH(1,(R$20>=Index_Tab!$G$5:$K$5)*(R$20<=Index_Tab!$G$17:$K$17),0))} -> FY27E | S18: {=INDEX(Index_Tab!$G$4:$K$4,MATCH(1,(S$20>=Index_Tab!$G$5:$K$5)*(S$20<=Index_Tab!$G$17:$K$17),0))} -> FY27E | T18: {=INDEX(Index_Tab!$G$4:$K$4,MATCH(1,(T$20>=Index_Tab!$G$5:$K$5)*(T$20<=Index_Tab!$G$17:$K$17),0))} -> FY27E | U18: {=INDEX(Index_Tab!$G$4:$K$4,MATCH(1,(U$20>=Index_Tab!$G$5:$K$5)*(U$20<=Index_Tab!$G$17:$K$17),0))} -> FY27E | V18: {=INDEX(Index_Tab!$G$4:$K$4,MATCH(1,(V$20>=Index_Tab!$G$5:$K$5)*(V$20<=Index_Tab!$G$17:$K$17),0))} -> FY27E | W18: {=INDEX(Index_Tab!$G$4:$K$4,MATCH(1,(W$20>=Index_Tab!$G$5:$K$5)*(W$20<=Index_Tab!$G$17:$K$17),0))} -> FY27E | X18: {=INDEX(Index_Tab!$G$4:$K$4,MATCH(1,(X$20>=Index_Tab!$G$5:$K$5)*(X$20<=Index_Tab!$G$17:$K$17),0))} -> FY27E | Y18: {=INDEX(Index_Tab!$G$4:$K$4,MATCH(1,(Y$20>=Index_Tab!$G$5:$K$5)*(Y$20<=Index_Tab!$G$17:$K$17),0))} -> FY27E | ... BY18: {=INDEX(Index_Tab!$G$4:$K$4,MATCH(1,(BY$20>=Index_Tab!$G$5:$K$5)*(BY$20<=Index_Tab!$G$17:$K$17),0))} -> FY31E
I19: ='Detailed Assumptions'!$E$17 -> FY26E | J19: ='Detailed Assumptions'!$F$17 -> FY27E | K19: ='Detailed Assumptions'!$G$17 -> FY28E | L19: ='Detailed Assumptions'!$H$17 -> FY29E | M19: ='Detailed Assumptions'!$I$17 -> FY30E | N19: ='Detailed Assumptions'!$J$17 -> FY31E | Q19: =EDATE(R19,-1) -> 46266 | R19: ='Detailed Assumptions'!$E$12 -> 46296 | S19: =R20+1 -> 46327 | T19: =S20+1 -> 46357 | U19: =T20+1 -> 46388 | V19: =U20+1 -> 46419 | W19: =V20+1 -> 46447 | X19: =W20+1 -> 46478 | Y19: =X20+1 -> 46508 | Z19: =Y20+1 -> 46539 | ... BY19: =BX20+1 -> 48092
I20: ='Detailed Assumptions'!$E$12-1 -> 46295 | J20: =EOMONTH(I20,12) -> 46660 | K20: =EOMONTH(J20,12) -> 47026 | L20: =EOMONTH(K20,12) -> 47391 | M20: =EOMONTH(L20,12) -> 47756 | N20: =EOMONTH(M20,12) -> 48121 | Q20: =EOMONTH(Q19,0) -> 46295 | R20: =EOMONTH(R19,0) -> 46326 | S20: =EOMONTH(S19,0) -> 46356 | T20: =EOMONTH(T19,0) -> 46387 | U20: =EOMONTH(U19,0) -> 46418 | V20: =EOMONTH(V19,0) -> 46446 | W20: =EOMONTH(W19,0) -> 46477 | X20: =EOMONTH(X19,0) -> 46507 | ... BY20: =EOMONTH(BY19,0) -> 48121
E22: Drinks gross profit (BCF + WSM) | I22: =Portfolio!N39 -> 16220326 | J22: =Portfolio!O39 -> 16977330 | K22: =Portfolio!P39 -> 17206443 | L22: =Portfolio!Q39 -> 17328213 | M22: =Portfolio!R39 -> 17347419 | N22: =Portfolio!S39 -> 17286720 | Q22: =Portfolio!V39 -> 0 | R22: =Portfolio!W39 -> 1423857.2 | S22: =Portfolio!X39 -> 1423857.2 | T22: =Portfolio!Y39 -> 1423857.2 | U22: =Portfolio!Z39 -> 1423857.2 | V22: =Portfolio!AA39 -> 1423857.2 | W22: =Portfolio!AB39 -> 1385632.8 | X22: =Portfolio!AC39 -> 1418590.9 | ... BY22: =Portfolio!CD39 -> 1401865.3
E23: Total rental income | I23: =Portfolio!N45 -> 11314203 | J23: =Portfolio!O45 -> 11610486 | K23: =Portfolio!P45 -> 11569977 | L23: =Portfolio!Q45 -> 11476062 | M23: =Portfolio!R45 -> 11310608 | N23: =Portfolio!S45 -> 11087204 | Q23: =Portfolio!V45 -> 0 | R23: =Portfolio!W45 -> 971506.83 | S23: =Portfolio!X45 -> 971506.83 | T23: =Portfolio!Y45 -> 971506.83 | U23: =Portfolio!Z45 -> 971506.83 | V23: =Portfolio!AA45 -> 971506.83 | W23: =Portfolio!AB45 -> 945426.11 | X23: =Portfolio!AC45 -> 972391.8 | ... BY23: =Portfolio!CD45 -> 904155.64
E24: Total other income | I24: =Portfolio!N52 -> 1964702 | J24: =Portfolio!O52 -> 1929539.6 | K24: =Portfolio!P52 -> 1824052.2 | L24: =Portfolio!Q52 -> 1718564.9 | M24: =Portfolio!R52 -> 1613077.5 | N24: =Portfolio!S52 -> 1507590.1 | Q24: =Portfolio!V52 -> 0 | R24: =Portfolio!W52 -> 163725.17 | S24: =Portfolio!X52 -> 163725.17 | T24: =Portfolio!Y52 -> 163725.17 | U24: =Portfolio!Z52 -> 163725.17 | V24: =Portfolio!AA52 -> 163725.17 | W24: =Portfolio!AB52 -> 159329.86 | X24: =Portfolio!AC52 -> 159329.86 | ... BY24: =Portfolio!CD52 -> 119772.1
E25: Net income (drinks GP + rent + other income) | I25: =SUM(I22:I24) -> 29499231 | J25: =SUM(J22:J24) -> 30517356 | K25: =SUM(K22:K24) -> 30600472 | L25: =SUM(L22:L24) -> 30522840 | M25: =SUM(M22:M24) -> 30271105 | N25: =SUM(N22:N24) -> 29881514 | Q25: =SUM(Q22:Q24) -> 0 | R25: =SUM(R22:R24) -> 2559089.2 | S25: =SUM(S22:S24) -> 2559089.2 | T25: =SUM(T22:T24) -> 2559089.2 | U25: =SUM(U22:U24) -> 2559089.2 | V25: =SUM(V22:V24) -> 2559089.2 | W25: =SUM(W22:W24) -> 2490388.8 | X25: =SUM(X22:X24) -> 2550312.5 | ... BY25: =SUM(BY22:BY24) -> 2425793
E27: Total pub costs | I27: =Portfolio!N59 -> -664289.16 | J27: =Portfolio!O59 -> -665448.32 | K27: =Portfolio!P59 -> -641649.83 | L27: =Portfolio!Q59 -> -616633.22 | M27: =Portfolio!R59 -> -590359.28 | N27: =Portfolio!S59 -> -562787.73 | Q27: =Portfolio!V59 -> 0 | R27: =Portfolio!W59 -> -56464.579 | S27: =Portfolio!X59 -> -56464.579 | T27: =Portfolio!Y59 -> -56464.579 | U27: =Portfolio!Z59 -> -56464.579 | V27: =Portfolio!AA59 -> -56464.579 | W27: =Portfolio!AB59 -> -54948.751 | X27: =Portfolio!AC59 -> -54948.751 | ... BY27: =Portfolio!CD59 -> -44711.27
E28: Outlet EBITDA | I28: =I25+I27 -> 28834942 | J28: =J25+J27 -> 29851908 | K28: =K25+K27 -> 29958822 | L28: =L25+L27 -> 29906207 | M28: =M25+M27 -> 29680745 | N28: =N25+N27 -> 29318726 | Q28: =Q25+Q27 -> 0 | R28: =R25+R27 -> 2502624.6 | S28: =S25+S27 -> 2502624.6 | T28: =T25+T27 -> 2502624.6 | U28: =U25+U27 -> 2502624.6 | V28: =V25+V27 -> 2502624.6 | W28: =W25+W27 -> 2435440 | X28: =X25+X27 -> 2495363.8 | ... BY28: =BY25+BY27 -> 2381081.7
E30: Overheads | I30: =Portfolio!N64 -> -2679600 | J30: =Portfolio!O64 -> -2698178 | K30: =Portfolio!P64 -> -2614763 | L30: =Portfolio!Q64 -> -2521776.6 | M30: =Portfolio!R64 -> -2419207.9 | N30: =Portfolio!S64 -> -2311200.4 | Q30: =Portfolio!V64 -> 0 | R30: =Portfolio!W64 -> -228810.25 | S30: =Portfolio!X64 -> -228810.25 | T30: =Portfolio!Y64 -> -228810.25 | U30: =Portfolio!Z64 -> -228810.25 | V30: =Portfolio!AA64 -> -228810.25 | W30: =Portfolio!AB64 -> -222867.13 | X30: =Portfolio!AC64 -> -222867.13 | ... BY30: =Portfolio!CD64 -> -183992.21
E31: Corporate EBITDA | I31: =I28+SUM(I30) -> 26155342 | J31: =J28+SUM(J30) -> 27153730 | K31: =K28+SUM(K30) -> 27344059 | L31: =L28+SUM(L30) -> 27384430 | M31: =M28+SUM(M30) -> 27261537 | N31: =N28+SUM(N30) -> 27007526 | Q31: =Q28+SUM(Q30) -> 0 | R31: =R28+SUM(R30) -> 2273814.3 | S31: =S28+SUM(S30) -> 2273814.3 | T31: =T28+SUM(T30) -> 2273814.3 | U31: =U28+SUM(U30) -> 2273814.3 | V31: =V28+SUM(V30) -> 2273814.3 | W31: =W28+SUM(W30) -> 2212572.9 | X31: =X28+SUM(X30) -> 2272496.7 | ... BY31: =BY28+SUM(BY30) -> 2197089.5
E33: Maintenance capex | I33: =Portfolio!N68 -> -3065576.1 | J33: =Portfolio!O68 -> -2388160 | K33: =Portfolio!P68 -> -2302752 | L33: =Portfolio!Q68 -> -2212972.4 | M33: =Portfolio!R68 -> -2118680.5 | N33: =Portfolio!S68 -> -2019731.8 | Q33: =Portfolio!V68 -> 0 | R33: =Portfolio!W68 -> -202640 | S33: =Portfolio!X68 -> -202640 | T33: =Portfolio!Y68 -> -202640 | U33: =Portfolio!Z68 -> -202640 | V33: =Portfolio!AA68 -> -202640 | W33: =Portfolio!AB68 -> -197200 | X33: =Portfolio!AC68 -> -197200 | ... BY33: =Portfolio!CD68 -> -160459.74
E34: Bad debts | I34: =Portfolio!N69 -> -432524.13 | J34: =Portfolio!O69 -> -447778.62 | K34: =Portfolio!P69 -> -449382.33 | L34: =Portfolio!Q69 -> -448593.1 | M34: =Portfolio!R69 -> -445211.18 | N34: =Portfolio!S69 -> -439780.9 | Q34: =Portfolio!V69 -> 0 | R34: =Portfolio!W69 -> -37539.369 | S34: =Portfolio!X69 -> -37539.369 | T34: =Portfolio!Y69 -> -37539.369 | U34: =Portfolio!Z69 -> -37539.369 | V34: =Portfolio!AA69 -> -37539.369 | W34: =Portfolio!AB69 -> -36531.6 | X34: =Portfolio!AC69 -> -37430.457 | ... BY34: =Portfolio!CD69 -> -35716.226
E35: Security costs re closed sites | I35: =Portfolio!N70 -> -300000 | J35: =Portfolio!O70 -> -307402.93 | K35: =Portfolio!P70 -> -314526.43 | L35: =Portfolio!Q70 -> -321272.72 | M35: =Portfolio!R70 -> -327569.22 | N35: =Portfolio!S70 -> -333924.15 | Q35: =Portfolio!V70 -> 0 | R35: =Portfolio!W70 -> -25616.911 | S35: =Portfolio!X70 -> -25616.911 | T35: =Portfolio!Y70 -> -25616.911 | U35: =Portfolio!Z70 -> -25616.911 | V35: =Portfolio!AA70 -> -25616.911 | W35: =Portfolio!AB70 -> -25616.911 | X35: =Portfolio!AC70 -> -25616.911 | ... BY35: =Portfolio!CD70 -> -27827.013
E36: Normalised operating CF | I36: =I31+SUM(I33:I35) -> 22357242 | J36: =J31+SUM(J33:J35) -> 24010388 | K36: =K31+SUM(K33:K35) -> 24277398 | L36: =L31+SUM(L33:L35) -> 24401592 | M36: =M31+SUM(M33:M35) -> 24370076 | N36: =N31+SUM(N33:N35) -> 24214089 | Q36: =Q31+SUM(Q33:Q35) -> 0 | R36: =R31+SUM(R33:R35) -> 2008018.1 | S36: =S31+SUM(S33:S35) -> 2008018.1 | T36: =T31+SUM(T33:T35) -> 2008018.1 | U36: =U31+SUM(U33:U35) -> 2008018.1 | V36: =V31+SUM(V33:V35) -> 2008018.1 | W36: =W31+SUM(W33:W35) -> 1953224.4 | X36: =X31+SUM(X33:X35) -> 2012249.3 | ... BY36: =BY31+SUM(BY33:BY35) -> 1973086.6
E38: Growth Capex | I38: =Portfolio!N74 -> -1391870.9 | J38: =Portfolio!O74 -> -1597966.6 | K38: =Portfolio!P74 -> -1546113.4 | L38: =Portfolio!Q74 -> -1488519.2 | M38: =Portfolio!R74 -> -1425078.2 | N38: =Portfolio!S74 -> -1356831.2 | Q38: =Portfolio!V74 -> 0 | R38: =Portfolio!W74 -> 0 | S38: =Portfolio!X74 -> 0 | T38: =Portfolio!Y74 -> 0 | U38: =Portfolio!Z74 -> 0 | V38: =Portfolio!AA74 -> 0 | W38: =Portfolio!AB74 -> -1597966.6 | X38: =Portfolio!AC74 -> 0 | ... BY38: =Portfolio!CD74 -> 0
E39: Asset disposal proceeds | I39: =Portfolio!N75 -> 0 | J39: =Portfolio!O75 -> 21007265 | K39: =Portfolio!P75 -> 22302773 | L39: =Portfolio!Q75 -> 23631372 | M39: =Portfolio!R75 -> 24988348 | N39: =Portfolio!S75 -> 26412339 | Q39: =Portfolio!V75 -> 0 | R39: =Portfolio!W75 -> 0 | S39: =Portfolio!X75 -> 0 | T39: =Portfolio!Y75 -> 0 | U39: =Portfolio!Z75 -> 0 | V39: =Portfolio!AA75 -> 10375982 | W39: =Portfolio!AB75 -> 0 | X39: =Portfolio!AC75 -> 0 | ... BY39: =Portfolio!CD75 -> 0
E40: Surplus land disposal proceeds | I40: =Portfolio!N76 -> 0 | J40: =Portfolio!O76 -> 833333.33 | K40: =Portfolio!P76 -> 2500000 | L40: =Portfolio!Q76 -> 4166666.7 | M40: =Portfolio!R76 -> 5000000 | N40: =Portfolio!S76 -> 5000000 | Q40: =Portfolio!V76 -> 0 | R40: =Portfolio!W76 -> 0 | S40: =Portfolio!X76 -> 0 | T40: =Portfolio!Y76 -> 0 | U40: =Portfolio!Z76 -> 0 | V40: =Portfolio!AA76 -> 0 | W40: =Portfolio!AB76 -> 0 | X40: =Portfolio!AC76 -> 0 | ... BY40: =Portfolio!CD76 -> 0
E41: Portfolio net cash flow | I41: =I36+SUM(I38:I40) -> 20965371 | J41: =J36+SUM(J38:J40) -> 44253020 | K41: =K36+SUM(K38:K40) -> 47534058 | L41: =L36+SUM(L38:L40) -> 50711112 | M41: =M36+SUM(M38:M40) -> 52933346 | N41: =N36+SUM(N38:N40) -> 54269597 | Q41: =Q36+SUM(Q38:Q40) -> 0 | R41: =R36+SUM(R38:R40) -> 2008018.1 | S41: =S36+SUM(S38:S40) -> 2008018.1 | T41: =T36+SUM(T38:T40) -> 2008018.1 | U41: =U36+SUM(U38:U40) -> 2008018.1 | V41: =V36+SUM(V38:V40) -> 12384000 | W41: =W36+SUM(W38:W40) -> 355257.75 | X41: =X36+SUM(X38:X40) -> 2012249.3 | ... BY41: =BY36+SUM(BY38:BY40) -> 1973086.6
E43: Purchase Price | I43: =SUMIFS($Q43:$BY43,$Q$18:$BY$18,I$19) -> -3.460193e+08 | J43: =SUMIFS($Q43:$BY43,$Q$18:$BY$18,J$19) -> 0 | K43: =SUMIFS($Q43:$BY43,$Q$18:$BY$18,K$19) -> 0 | L43: =SUMIFS($Q43:$BY43,$Q$18:$BY$18,L$19) -> 0 | M43: =SUMIFS($Q43:$BY43,$Q$18:$BY$18,M$19) -> 0 | N43: =SUMIFS($Q43:$BY43,$Q$18:$BY$18,N$19) -> 0 | Q43: =IF(Q$20=$I$5,-$I$28*$I$6,0) -> -3.460193e+08 | R43: =IF(R$20=$I$5,-$I$28*$I$6,0) -> 0 | S43: =IF(S$20=$I$5,-$I$28*$I$6,0) -> 0 | T43: =IF(T$20=$I$5,-$I$28*$I$6,0) -> 0 | U43: =IF(U$20=$I$5,-$I$28*$I$6,0) -> 0 | V43: =IF(V$20=$I$5,-$I$28*$I$6,0) -> 0 | W43: =IF(W$20=$I$5,-$I$28*$I$6,0) -> 0 | X43: =IF(X$20=$I$5,-$I$28*$I$6,0) -> 0 | ... BY43: =IF(BY$20=$I$5,-$I$28*$I$6,0) -> 0
E44: Exit Proceeds | I44: =SUMIFS($Q44:$BY44,$Q$18:$BY$18,I$19) -> 0 | J44: =SUMIFS($Q44:$BY44,$Q$18:$BY$18,J$19) -> 0 | K44: =SUMIFS($Q44:$BY44,$Q$18:$BY$18,K$19) -> 0 | L44: =SUMIFS($Q44:$BY44,$Q$18:$BY$18,L$19) -> 0 | M44: =SUMIFS($Q44:$BY44,$Q$18:$BY$18,M$19) -> 0 | N44: =SUMIFS($Q44:$BY44,$Q$18:$BY$18,N$19) -> 3.4287577e+08 | Q44: =IF(Q$20=$I$11,Q28*12*$I$10,0) -> 0 | R44: =IF(R$20=$I$11,R28*12*$I$10,0) -> 0 | S44: =IF(S$20=$I$11,S28*12*$I$10,0) -> 0 | T44: =IF(T$20=$I$11,T28*12*$I$10,0) -> 0 | U44: =IF(U$20=$I$11,U28*12*$I$10,0) -> 0 | V44: =IF(V$20=$I$11,V28*12*$I$10,0) -> 0 | W44: =IF(W$20=$I$11,W28*12*$I$10,0) -> 0 | X44: =IF(X$20=$I$11,X28*12*$I$10,0) -> 0 | ... BY44: =IF(BY$20=$I$11,BY28*12*$I$10,0) -> 3.4287577e+08
E45: Transaction Costs | I45: =SUMIFS($Q45:$BY45,$Q$18:$BY$18,I$19) -> -3460193 | J45: =SUMIFS($Q45:$BY45,$Q$18:$BY$18,J$19) -> 0 | K45: =SUMIFS($Q45:$BY45,$Q$18:$BY$18,K$19) -> 0 | L45: =SUMIFS($Q45:$BY45,$Q$18:$BY$18,L$19) -> 0 | M45: =SUMIFS($Q45:$BY45,$Q$18:$BY$18,M$19) -> 0 | N45: =SUMIFS($Q45:$BY45,$Q$18:$BY$18,N$19) -> -3428757.7 | Q45: =Q43*$I$7+-Q44*$I$12 -> -3460193 | R45: =R43*$I$7+-R44*$I$12 -> 0 | S45: =S43*$I$7+-S44*$I$12 -> 0 | T45: =T43*$I$7+-T44*$I$12 -> 0 | U45: =U43*$I$7+-U44*$I$12 -> 0 | V45: =V43*$I$7+-V44*$I$12 -> 0 | W45: =W43*$I$7+-W44*$I$12 -> 0 | X45: =X43*$I$7+-X44*$I$12 -> 0 | ... BY45: =BY43*$I$7+-BY44*$I$12 -> -3428757.7
E46: Unlevered portfolio net cash flow | I46: =SUM(I41:I45) -> -3.2851413e+08 | J46: =SUM(J41:J45) -> 44253020 | K46: =SUM(K41:K45) -> 47534058 | L46: =SUM(L41:L45) -> 50711112 | M46: =SUM(M41:M45) -> 52933346 | N46: =SUM(N41:N45) -> 3.9371661e+08 | Q46: =SUM(Q41:Q45) -> -3.494795e+08 | R46: =SUM(R41:R45) -> 2008018.1 | S46: =SUM(S41:S45) -> 2008018.1 | T46: =SUM(T41:T45) -> 2008018.1 | U46: =SUM(U41:U45) -> 2008018.1 | V46: =SUM(V41:V45) -> 12384000 | W46: =SUM(W41:W45) -> 355257.75 | X46: =SUM(X41:X45) -> 2012249.3 | ... BY46: =SUM(BY41:BY45) -> 3.414201e+08
E47: Unlevered running cash yield (incl. disposal proceeds) | J47: =AVERAGEIF($Q$18:$BY$18,J$19,$Q$47:$BY$47) -> 0.12662551 | K47: =AVERAGEIF($Q$18:$BY$18,K$19,$Q$47:$BY$47) -> 0.13601387 | L47: =AVERAGEIF($Q$18:$BY$18,L$19,$Q$47:$BY$47) -> 0.14510468 | M47: =AVERAGEIF($Q$18:$BY$18,M$19,$Q$47:$BY$47) -> 0.15146338 | N47: =AVERAGEIF($Q$18:$BY$18,N$19,$Q$47:$BY$47) -> 0.15528693 | R47: =(R41*12)/-$Q$46 -> 0.06894887 | S47: =(S41*12)/-$Q$46 -> 0.06894887 | T47: =(T41*12)/-$Q$46 -> 0.06894887 | U47: =(U41*12)/-$Q$46 -> 0.06894887 | V47: =(V41*12)/-$Q$46 -> 0.42522667 | W47: =(W41*12)/-$Q$46 -> 0.012198407 | X47: =(X41*12)/-$Q$46 -> 0.069094157 | Y47: =(Y41*12)/-$Q$46 -> 0.069094157 | ... BY47: =(BY41*12)/-$Q$46 -> 0.067749435
E49: Financing Cashflows | I49: =SUMIFS($Q49:$BY49,$Q$18:$BY$18,I$19) -> 1.9982615e+08 | J49: =SUMIFS($Q49:$BY49,$Q$18:$BY$18,J$19) -> -31397764 | K49: =SUMIFS($Q49:$BY49,$Q$18:$BY$18,K$19) -> -31005739 | L49: =SUMIFS($Q49:$BY49,$Q$18:$BY$18,L$19) -> -30559065 | M49: =SUMIFS($Q49:$BY49,$Q$18:$BY$18,M$19) -> -30052726 | N49: =SUMIFS($Q49:$BY49,$Q$18:$BY$18,N$19) -> -1.5319156e+08 | Q49: ='Debt Schedule'!R51 -> 1.9982615e+08 | R49: ='Debt Schedule'!S51 -> -1476156.8 | S49: ='Debt Schedule'!T51 -> -1476156.8 | T49: ='Debt Schedule'!U51 -> -1476156.8 | U49: ='Debt Schedule'!V51 -> -1476156.8 | V49: ='Debt Schedule'!W51 -> -8436711.6 | W49: ='Debt Schedule'!X51 -> -1425251.9 | X49: ='Debt Schedule'!Y51 -> -1425251.9 | ... BY49: ='Debt Schedule'!BZ51 -> -1.2457691e+08
E50: Levered portfolio net cash flow | I50: =I49+I46 -> -1.2868798e+08 | J50: =J49+J46 -> 12855256 | K50: =K49+K46 -> 16528319 | L50: =L49+L46 -> 20152047 | M50: =M49+M46 -> 22880619 | N50: =N49+N46 -> 2.4052505e+08 | Q50: =Q49+Q46 -> -1.4965335e+08 | R50: =R49+R46 -> 531861.25 | S50: =S49+S46 -> 531861.25 | T50: =T49+T46 -> 531861.25 | U50: =U49+U46 -> 531861.25 | V50: =V49+V46 -> 3947288.8 | W50: =W49+W46 -> -1069994.2 | X50: =X49+X46 -> 586997.34 | ... BY50: =BY49+BY46 -> 2.1684319e+08
E51: Levered running cash yield (incl. disposal proceeds) | J51: =AVERAGEIF($Q$18:$BY$18,J$19,$Q$51:$BY$51) -> 0.085900223 | K51: =AVERAGEIF($Q$18:$BY$18,K$19,$Q$51:$BY$51) -> 0.11044403 | L51: =AVERAGEIF($Q$18:$BY$18,L$19,$Q$51:$BY$51) -> 0.13465817 | M51: =AVERAGEIF($Q$18:$BY$18,M$19,$Q$51:$BY$51) -> 0.15289079 | N51: =AVERAGEIF($Q$18:$BY$18,N$19,$Q$51:$BY$51) -> 0.10451077 | R51: =(SUM(R41,R49)*12)/-$Q$50 -> 0.042647459 | S51: =(SUM(S41,S49)*12)/-$Q$50 -> 0.042647459 | T51: =(SUM(T41,T49)*12)/-$Q$50 -> 0.042647459 | U51: =(SUM(U41,U49)*12)/-$Q$50 -> 0.042647459 | V51: =(SUM(V41,V49)*12)/-$Q$50 -> 0.31651457 | W51: =(SUM(W41,W49)*12)/-$Q$50 -> -0.085797815 | X51: =(SUM(X41,X49)*12)/-$Q$50 -> 0.047068563 | Y51: =(SUM(Y41,Y49)*12)/-$Q$50 -> 0.047068563 | ... BX51: =(SUM(BX41,BX49)*12)/-$Q$50 -> 0.64365449 | BY51: =(SUM(BY41,BX49)*12)/-$Q$50 -> -0.64480792
...

Sheet Debt Schedule
B2: X | D2: Debt schedule - initial portfolio
J4: ='Detailed Assumptions'!F$17 -> FY27E | K4: ='Detailed Assumptions'!G$17 -> FY28E | L4: ='Detailed Assumptions'!H$17 -> FY29E | M4: ='Detailed Assumptions'!I$17 -> FY30E | N4: ='Detailed Assumptions'!J$17 -> FY31E | R4: {=INDEX(Index_Tab!$F$4:$K$4,MATCH(1,(R6>=Index_Tab!$F$5:$K$5)*(R6<=Index_Tab!$F$17:$K$17),0))} -> FY26E | S4: {=INDEX(Index_Tab!$F$4:$K$4,MATCH(1,(S6>=Index_Tab!$F$5:$K$5)*(S6<=Index_Tab!$F$17:$K$17),0))} -> FY27E | T4: {=INDEX(Index_Tab!$F$4:$K$4,MATCH(1,(T6>=Index_Tab!$F$5:$K$5)*(T6<=Index_Tab!$F$17:$K$17),0))} -> FY27E | U4: {=INDEX(Index_Tab!$F$4:$K$4,MATCH(1,(U6>=Index_Tab!$F$5:$K$5)*(U6<=Index_Tab!$F$17:$K$17),0))} -> FY27E | V4: {=INDEX(Index_Tab!$F$4:$K$4,MATCH(1,(V6>=Index_Tab!$F$5:$K$5)*(V6<=Index_Tab!$F$17:$K$17),0))} -> FY27E | W4: {=INDEX(Index_Tab!$F$4:$K$4,MATCH(1,(W6>=Index_Tab!$F$5:$K$5)*(W6<=Index_Tab!$F$17:$K$17),0))} -> FY27E | X4: {=INDEX(Index_Tab!$F$4:$K$4,MATCH(1,(X6>=Index_Tab!$F$5:$K$5)*(X6<=Index_Tab!$F$17:$K$17),0))} -> FY27E | Y4: {=INDEX(Index_Tab!$F$4:$K$4,MATCH(1,(Y6>=Index_Tab!$F$5:$K$5)*(Y6<=Index_Tab!$F$17:$K$17),0))} -> FY27E | ... BZ4: {=INDEX(Index_Tab!$F$4:$K$4,MATCH(1,(BZ6>=Index_Tab!$F$5:$K$5)*(BZ6<=Index_Tab!$F$17:$K$17),0))} -> FY31E
D5: BoP | J5: =Index_Tab!G5 -> 46296 | K5: =J6+1 -> 46661 | L5: =K6+1 -> 47027 | M5: =L6+1 -> 47392 | N5: =M6+1 -> 47757 | R5: =EDATE(S5,-1) -> 46266 | S5: =J5 -> 46296 | T5: =S6+1 -> 46327 | U5: =T6+1 -> 46357 | V5: =U6+1 -> 46388 | W5: =V6+1 -> 46419 | X5: =W6+1 -> 46447 | Y5: =X6+1 -> 46478 | Z5: =Y6+1 -> 46508 | AA5: =Z6+1 -> 46539 | ... BZ5: =BY6+1 -> 48092
D6: EoP | J6: =EOMONTH(J5,11) -> 46660 | K6: =EOMONTH(K5,11) -> 47026 | L6: =EOMONTH(L5,11) -> 47391 | M6: =EOMONTH(M5,11) -> 47756 | N6: =EOMONTH(N5,11) -> 48121 | R6: =EOMONTH(R5,0) -> 46295 | S6: =EOMONTH(S5,0) -> 46326 | T6: =EOMONTH(T5,0) -> 46356 | U6: =EOMONTH(U5,0) -> 46387 | V6: =EOMONTH(V5,0) -> 46418 | W6: =EOMONTH(W5,0) -> 46446 | X6: =EOMONTH(X5,0) -> 46477 | Y6: =EOMONTH(Y5,0) -> 46507 | ... BZ6: =EOMONTH(BZ5,0) -> 48121
D8: Loan Start Date | E8: ='Returns Analysis'!I5 -> 46295
D9: Repayment Date | E9: ='Detailed Assumptions'!$E$141 -> 48121
D10: Loan Amount | E10: =E15 -> 2.0184459e+08
D12: Outlet EBITDA (pre-OHs)" | E12: =Portfolio!N61 -> 28834942
D13: EBITDA used for debt sizing (pre overheads) | E13: =E12 -> 28834942
D14: EBITDA Multiple | E14: ='Detailed Assumptions'!$E$140 -> 7
D15: Implied quantum | E15: =E13*E14 -> 2.0184459e+08
D18: All-In Cost | E18: =E22+E19 -> 0.08776
D19: Margin | E19: ='Detailed Assumptions'!$E$143 -> 0.0475
D20: Interest Method | E20: ='Detailed Assumptions'!$E$144 -> Current
D21: Type | E21: ='Detailed Assumptions'!$E$145 -> Fixed
D22: 5Y Swap | E22: ='Detailed Assumptions'!$E$146 -> 0.04026
D24: Commitment Fee % | E24: ='Detailed Assumptions'!$E$147 -> 0
D25: Commitment Fee Method | E25: ='Detailed Assumptions'!$E$148 -> Current
D26: UFF | E26: ='Detailed Assumptions'!$E$149 -> 0.01
D27: Amortisation | E27: ='Detailed Assumptions'!$E$150 -> 0
D28: Exit Fee | E28: ='Detailed Assumptions'!$E$151 -> 0.01
D29: Release Pricing Premium | E29: ='Detailed Assumptions'!$E$152 -> 0.15
D30: Allocated loan amount (% LTV) | E30: ='Detailed Assumptions'!$E$153 -> 0.58333333
D33: Disposal Proceeds | J33: =SUMIFS($S33:$BZ33,$S$4:$BZ$4,J$4) -> 21007265 | K33: =SUMIFS($S33:$BZ33,$S$4:$BZ$4,K$4) -> 22302773 | L33: =SUMIFS($S33:$BZ33,$S$4:$BZ$4,L$4) -> 23631372 | M33: =SUMIFS($S33:$BZ33,$S$4:$BZ$4,M$4) -> 24988348 | N33: =SUMIFS($S33:$BZ33,$S$4:$BZ$4,N$4) -> 26412339 | R33: =IFERROR(INDEX(Portfolio!$W$75:$CD$75,MATCH('Debt Schedule'!R$6,Portfolio!$W$4:$CD$4,0)),0) -> 0 | S33: =IFERROR(INDEX(Portfolio!$W$75:$CD$75,MATCH('Debt Schedule'!S$6,Portfolio!$W$4:$CD$4,0)),0) -> 0 | T33: =IFERROR(INDEX(Portfolio!$W$75:$CD$75,MATCH('Debt Schedule'!T$6,Portfolio!$W$4:$CD$4,0)),0) -> 0 | U33: =IFERROR(INDEX(Portfolio!$W$75:$CD$75,MATCH('Debt Schedule'!U$6,Portfolio!$W$4:$CD$4,0)),0) -> 0 | V33: =IFERROR(INDEX(Portfolio!$W$75:$CD$75,MATCH('Debt Schedule'!V$6,Portfolio!$W$4:$CD$4,0)),0) -> 0 | W33: =IFERROR(INDEX(Portfolio!$W$75:$CD$75,MATCH('Debt Schedule'!W$6,Portfolio!$W$4:$CD$4,0)),0) -> 10375982 | X33: =IFERROR(INDEX(Portfolio!$W$75:$CD$75,MATCH('Debt Schedule'!X$6,Portfolio!$W$4:$CD$4,0)),0) -> 0 | Y33: =IFERROR(INDEX(Portfolio!$W$75:$CD$75,MATCH('Debt Schedule'!Y$6,Portfolio!$W$4:$CD$4,0)),0) -> 0 | ... BZ33: =IFERROR(INDEX(Portfolio!$W$75:$CD$75,MATCH('Debt Schedule'!BZ$6,Portfolio!$W$4:$CD$4,0)),0) -> 0
D35: Opening Balance | J35: {=INDEX($S35:$BZ35,0,MATCH(EOMONTH(J$6,-11),$S$6:$BZ$6,0))} -> 2.0184459e+08 | K35: {=INDEX($S35:$BZ35,0,MATCH(EOMONTH(K$6,-11),$S$6:$BZ$6,0))} -> 1.8775222e+08 | L35: {=INDEX($S35:$BZ35,0,MATCH(EOMONTH(L$6,-11),$S$6:$BZ$6,0))} -> 1.7279078e+08 | M35: {=INDEX($S35:$BZ35,0,MATCH(EOMONTH(M$6,-11),$S$6:$BZ$6,0))} -> 1.5693807e+08 | N35: {=INDEX($S35:$BZ35,0,MATCH(EOMONTH(N$6,-11),$S$6:$BZ$6,0))} -> 1.4017505e+08 | R35: 0 | S35: =R49 -> 2.0184459e+08 | T35: =S49 -> 2.0184459e+08 | U35: =T49 -> 2.0184459e+08 | V35: =U49 -> 2.0184459e+08 | W35: =V49 -> 2.0184459e+08 | X35: =W49 -> 1.9488404e+08 | Y35: =X49 -> 1.9488404e+08 | Z35: =Y49 -> 1.9488404e+08 | ... BZ35: =BY49 -> 1.2245677e+08
D36: Drawdown | J36: =SUMIFS($S36:$BZ36,$S$4:$BZ$4,J$4) -> 0 | K36: =SUMIFS($S36:$BZ36,$S$4:$BZ$4,K$4) -> 0 | L36: =SUMIFS($S36:$BZ36,$S$4:$BZ$4,L$4) -> 0 | M36: =SUMIFS($S36:$BZ36,$S$4:$BZ$4,M$4) -> 0 | N36: =SUMIFS($S36:$BZ36,$S$4:$BZ$4,N$4) -> 0 | R36: =IF(R$6=$E$8,$E$10,0) -> 2.0184459e+08 | S36: =IF(S$6=$E$8,$E$10,0) -> 0 | T36: =IF(T$6=$E$8,$E$10,0) -> 0 | U36: =IF(U$6=$E$8,$E$10,0) -> 0 | V36: =IF(V$6=$E$8,$E$10,0) -> 0 | W36: =IF(W$6=$E$8,$E$10,0) -> 0 | X36: =IF(X$6=$E$8,$E$10,0) -> 0 | Y36: =IF(Y$6=$E$8,$E$10,0) -> 0 | ... BZ36: =IF(BZ$6=$E$8,$E$10,0) -> 0
D37: Upfront Fee | J37: =SUMIFS($S37:$BZ37,$S$4:$BZ$4,J$4) -> 0 | K37: =SUMIFS($S37:$BZ37,$S$4:$BZ$4,K$4) -> 0 | L37: =SUMIFS($S37:$BZ37,$S$4:$BZ$4,L$4) -> 0 | M37: =SUMIFS($S37:$BZ37,$S$4:$BZ$4,M$4) -> 0 | N37: =SUMIFS($S37:$BZ37,$S$4:$BZ$4,N$4) -> 0 | R37: =-IF(R$6=$E8,$E10*$E26,0) -> -2018445.9 | S37: =-IF(S$6=$E8,$E10*$E26,0) -> 0 | T37: =-IF(T$6=$E8,$E10*$E26,0) -> 0 | U37: =-IF(U$6=$E8,$E10*$E26,0) -> 0 | V37: =-IF(V$6=$E8,$E10*$E26,0) -> 0 | W37: =-IF(W$6=$E8,$E10*$E26,0) -> 0 | X37: =-IF(X$6=$E8,$E10*$E26,0) -> 0 | Y37: =-IF(Y$6=$E8,$E10*$E26,0) -> 0 | ... BZ37: =-IF(BZ$6=$E8,$E10*$E26,0) -> 0
D38: Commitment Fee | J38: =SUMIFS($S38:$BZ38,$S$4:$BZ$4,J$4) -> 0 | K38: =SUMIFS($S38:$BZ38,$S$4:$BZ$4,K$4) -> 0 | L38: =SUMIFS($S38:$BZ38,$S$4:$BZ$4,L$4) -> 0 | M38: =SUMIFS($S38:$BZ38,$S$4:$BZ$4,M$4) -> 0 | N38: =SUMIFS($S38:$BZ38,$S$4:$BZ$4,N$4) -> 0 | R38: =IF(AND(R$6>=$E8,R$6<$E9),-((($E10)-SUM(R36:$S36))*($E24))/12,0) -> 0 | S38: =IF(AND(S$6>=$E8,S$6<$E9),-((($E10)-SUM($S36:S36))*($E24))/12,0) -> 0 | T38: =IF(AND(T$6>=$E8,T$6<$E9),-((($E10)-SUM($S36:T36))*($E24))/12,0) -> 0 | U38: =IF(AND(U$6>=$E8,U$6<$E9),-((($E10)-SUM($S36:U36))*($E24))/12,0) -> 0 | V38: =IF(AND(V$6>=$E8,V$6<$E9),-((($E10)-SUM($S36:V36))*($E24))/12,0) -> 0 | W38: =IF(AND(W$6>=$E8,W$6<$E9),-((($E10)-SUM($S36:W36))*($E24))/12,0) -> 0 | X38: =IF(AND(X$6>=$E8,X$6<$E9),-((($E10)-SUM($S36:X36))*($E24))/12,0) -> 0 | Y38: =IF(AND(Y$6>=$E8,Y$6<$E9),-((($E10)-SUM($S36:Y36))*($E24))/12,0) -> 0 | Z38: =IF(AND(Z$6>=$E8,Z$6<$E9),-((($E10)-SUM($S36:Z36))*($E24))/12,0) -> 0 | ... BZ38: =IF(AND(BZ$6>=$E8,BZ$6<$E9),-((($E10)-SUM($S36:BZ36))*($E24))/12,0) -> 0
D39: Paid | J39: =SUMIFS($S39:$BZ39,$S$4:$BZ$4,J$4) -> 0 | K39: =SUMIFS($S39:$BZ39,$S$4:$BZ$4,K$4) -> 0 | L39: =SUMIFS($S39:$BZ39,$S$4:$BZ$4,L$4) -> 0 | M39: =SUMIFS($S39:$BZ39,$S$4:$BZ$4,M$4) -> 0 | N39: =SUMIFS($S39:$BZ39,$S$4:$BZ$4,N$4) -> 0 | R39: =IF($E$25="Current",R$38,0) -> 0 | S39: =IF($E$25="Current",S$38,0) -> 0 | T39: =IF($E$25="Current",T$38,0) -> 0 | U39: =IF($E$25="Current",U$38,0) -> 0 | V39: =IF($E$25="Current",V$38,0) -> 0 | W39: =IF($E$25="Current",W$38,0) -> 0 | X39: =IF($E$25="Current",X$38,0) -> 0 | Y39: =IF($E$25="Current",Y$38,0) -> 0 | ... BZ39: =IF($E$25="Current",BZ$38,0) -> 0
D40: PIK | J40: =SUMIFS($S40:$BZ40,$S$4:$BZ$4,J$4) -> 0 | K40: =SUMIFS($S40:$BZ40,$S$4:$BZ$4,K$4) -> 0 | L40: =SUMIFS($S40:$BZ40,$S$4:$BZ$4,L$4) -> 0 | M40: =SUMIFS($S40:$BZ40,$S$4:$BZ$4,M$4) -> 0 | N40: =SUMIFS($S40:$BZ40,$S$4:$BZ$4,N$4) -> 0 | R40: =IF($E$25="PIK",-R$38,0) -> 0 | S40: =IF($E$25="PIK",-S$38,0) -> 0 | T40: =IF($E$25="PIK",-T$38,0) -> 0 | U40: =IF($E$25="PIK",-U$38,0) -> 0 | V40: =IF($E$25="PIK",-V$38,0) -> 0 | W40: =IF($E$25="PIK",-W$38,0) -> 0 | X40: =IF($E$25="PIK",-X$38,0) -> 0 | Y40: =IF($E$25="PIK",-Y$38,0) -> 0 | ... BZ40: =IF($E$25="PIK",-BZ$38,0) -> 0
D41: Interest | J41: =SUMIFS($S41:$BZ41,$S$4:$BZ$4,J$4) -> -17305390 | K41: =SUMIFS($S41:$BZ41,$S$4:$BZ$4,K$4) -> -16044295 | L41: =SUMIFS($S41:$BZ41,$S$4:$BZ$4,L$4) -> -14706353 | M41: =SUMIFS($S41:$BZ41,$S$4:$BZ$4,M$4) -> -13289710 | N41: =SUMIFS($S41:$BZ41,$S$4:$BZ$4,N$4) -> -11791941 | R41: =-(R35*(IF($E$21="Floating",R$53+$E$19,$E$18))/12) -> 0 | S41: =-(S35*(IF($E$21="Floating",S$53+$E$19,$E$18))/12) -> -1476156.8 | T41: =-(T35*(IF($E$21="Floating",T$53+$E$19,$E$18))/12) -> -1476156.8 | U41: =-(U35*(IF($E$21="Floating",U$53+$E$19,$E$18))/12) -> -1476156.8 | V41: =-(V35*(IF($E$21="Floating",V$53+$E$19,$E$18))/12) -> -1476156.8 | W41: =-(W35*(IF($E$21="Floating",W$53+$E$19,$E$18))/12) -> -1476156.8 | X41: =-(X35*(IF($E$21="Floating",X$53+$E$19,$E$18))/12) -> -1425251.9 | Y41: =-(Y35*(IF($E$21="Floating",Y$53+$E$19,$E$18))/12) -> -1425251.9 | ... BZ41: =-(BZ35*(IF($E$21="Floating",BZ$53+$E$19,$E$18))/12) -> -895567.19
D42: Paid | J42: =SUMIFS($S42:$BZ42,$S$4:$BZ$4,J$4) -> -17305390 | K42: =SUMIFS($S42:$BZ42,$S$4:$BZ$4,K$4) -> -16044295 | L42: =SUMIFS($S42:$BZ42,$S$4:$BZ$4,L$4) -> -14706353 | M42: =SUMIFS($S42:$BZ42,$S$4:$BZ$4,M$4) -> -13289710 | N42: =SUMIFS($S42:$BZ42,$S$4:$BZ$4,N$4) -> -11791941 | R42: =IF($E$20="Current",R$41,0) -> 0 | S42: =IF($E$20="Current",S$41,0) -> -1476156.8 | T42: =IF($E$20="Current",T$41,0) -> -1476156.8 | U42: =IF($E$20="Current",U$41,0) -> -1476156.8 | V42: =IF($E$20="Current",V$41,0) -> -1476156.8 | W42: =IF($E$20="Current",W$41,0) -> -1476156.8 | X42: =IF($E$20="Current",X$41,0) -> -1425251.9 | Y42: =IF($E$20="Current",Y$41,0) -> -1425251.9 | ... BZ42: =IF($E$20="Current",BZ$41,0) -> -895567.19
D43: PIK | J43: =SUMIFS($S43:$BZ43,$S$4:$BZ$4,J$4) -> 0 | K43: =SUMIFS($S43:$BZ43,$S$4:$BZ$4,K$4) -> 0 | L43: =SUMIFS($S43:$BZ43,$S$4:$BZ$4,L$4) -> 0 | M43: =SUMIFS($S43:$BZ43,$S$4:$BZ$4,M$4) -> 0 | N43: =SUMIFS($S43:$BZ43,$S$4:$BZ$4,N$4) -> 0 | R43: =IF($E$20="PIK",-R$41,0) -> 0 | S43: =IF($E$20="PIK",-S$41,0) -> 0 | T43: =IF($E$20="PIK",-T$41,0) -> 0 | U43: =IF($E$20="PIK",-U$41,0) -> 0 | V43: =IF($E$20="PIK",-V$41,0) -> 0 | W43: =IF($E$20="PIK",-W$41,0) -> 0 | X43: =IF($E$20="PIK",-X$41,0) -> 0 | Y43: =IF($E$20="PIK",-Y$41,0) -> 0 | ... BZ43: =IF($E$20="PIK",-BZ$41,0) -> 0
D44: Amortisation | J44: =SUMIFS($S44:$BZ44,$S$4:$BZ$4,J$4) -> -14092373 | K44: =SUMIFS($S44:$BZ44,$S$4:$BZ$4,K$4) -> -14961444 | L44: =SUMIFS($S44:$BZ44,$S$4:$BZ$4,L$4) -> -15852712 | M44: =SUMIFS($S44:$BZ44,$S$4:$BZ$4,M$4) -> -16763016 | N44: =SUMIFS($S44:$BZ44,$S$4:$BZ$4,N$4) -> -17718277 | R44: =R45+R46 -> 0 | S44: =S45+S46 -> 0 | T44: =T45+T46 -> 0 | U44: =U45+U46 -> 0 | V44: =V45+V46 -> 0 | W44: =W45+W46 -> -6960554.8 | X44: =X45+X46 -> 0 | Y44: =Y45+Y46 -> 0 | ... BZ44: =BZ45+BZ46 -> 0
D45: Contracted Amortisation | J45: =SUMIFS($S45:$BZ45,$S$4:$BZ$4,J$4) -> 0 | K45: =SUMIFS($S45:$BZ45,$S$4:$BZ$4,K$4) -> 0 | L45: =SUMIFS($S45:$BZ45,$S$4:$BZ$4,L$4) -> 0 | M45: =SUMIFS($S45:$BZ45,$S$4:$BZ$4,M$4) -> 0 | N45: =SUMIFS($S45:$BZ45,$S$4:$BZ$4,N$4) -> 0 | R45: =(-R$35*$E$27)/12 -> 0 | S45: =(-S$35*$E$27)/12 -> 0 | T45: =(-T$35*$E$27)/12 -> 0 | U45: =(-U$35*$E$27)/12 -> 0 | V45: =(-V$35*$E$27)/12 -> 0 | W45: =(-W$35*$E$27)/12 -> 0 | X45: =(-X$35*$E$27)/12 -> 0 | Y45: =(-Y$35*$E$27)/12 -> 0 | ... BZ45: =(-BZ$35*$E$27)/12 -> 0
D46: Asset Sales Amortisation | J46: =SUMIFS($S46:$BZ46,$S$4:$BZ$4,J$4) -> -14092373 | K46: =SUMIFS($S46:$BZ46,$S$4:$BZ$4,K$4) -> -14961444 | L46: =SUMIFS($S46:$BZ46,$S$4:$BZ$4,L$4) -> -15852712 | M46: =SUMIFS($S46:$BZ46,$S$4:$BZ$4,M$4) -> -16763016 | N46: =SUMIFS($S46:$BZ46,$S$4:$BZ$4,N$4) -> -17718277 | R46: =(-IF((1+$E$29)*($E$30*(SUM(R$33:$S$33)))>$R$36,(MAX(0,($R$36-((1+$E$29)*$E$30*(SUM(R$33:$S$33)))))),((1+$E$29))*($E$30*R$33))) -> 0 | S46: =(-IF((1+$E$29)*($E$30*(SUM(S$33:$S$33)))>$R$36,(MAX(0,($R$36-((1+$E$29)*$E$30*(SUM(S$33:$S$33)))))),((1+$E$29))*($E$30*S$33))) -> 0 | T46: =(-IF((1+$E$29)*($E$30*(SUM($S$33:T$33)))>$R$36,(MAX(0,($R$36-((1+$E$29)*$E$30*(SUM($S$33:T$33)))))),((1+$E$29))*($E$30*T$33))) -> 0 | U46: =(-IF((1+$E$29)*($E$30*(SUM($S$33:U$33)))>$R$36,(MAX(0,($R$36-((1+$E$29)*$E$30*(SUM($S$33:U$33)))))),((1+$E$29))*($E$30*U$33))) -> 0 | V46: =(-IF((1+$E$29)*($E$30*(SUM($S$33:V$33)))>$R$36,(MAX(0,($R$36-((1+$E$29)*$E$30*(SUM($S$33:V$33)))))),((1+$E$29))*($E$30*V$33))) -> 0 | W46: =(-IF((1+$E$29)*($E$30*(SUM($S$33:W$33)))>$R$36,(MAX(0,($R$36-((1+$E$29)*$E$30*(SUM($S$33:W$33)))))),((1+$E$29))*($E$30*W$33))) -> -6960554.8 | X46: =(-IF((1+$E$29)*($E$30*(SUM($S$33:X$33)))>$R$36,(MAX(0,($R$36-((1+$E$29)*$E$30*(SUM($S$33:X$33)))))),((1+$E$29))*($E$30*X$33))) -> 0 | Y46: =(-IF((1+$E$29)*($E$30*(SUM($S$33:Y$33)))>$R$36,(MAX(0,($R$36-((1+$E$29)*$E$30*(SUM($S$33:Y$33)))))),((1+$E$29))*($E$30*Y$33))) -> 0 | Z46: =(-IF((1+$E$29)*($E$30*(SUM($S$33:Z$33)))>$R$36,(MAX(0,($R$36-((1+$E$29)*$E$30*(SUM($S$33:Z$33)))))),((1+$E$29))*($E$30*Z$33))) -> 0 | AA46: =(-IF((1+$E$29)*($E$30*(SUM($S$33:AA$33)))>$R$36,(MAX(0,($R$36-((1+$E$29)*$E$30*(SUM($S$33:AA$33)))))),((1+$E$29))*($E$30*AA$33))) -> 0 | ... BZ46: =(-IF((1+$E$29)*($E$30*(SUM($S$33:BZ$33)))>$R$36,(MAX(0,($R$36-((1+$E$29)*$E$30*(SUM($S$33:BZ$33)))))),((1+$E$29))*($E$30*BZ$33))) -> 0
D47: Exit Fee | J47: =SUMIFS($S47:$BZ47,$S$4:$BZ$4,J$4) -> 0 | K47: =SUMIFS($S47:$BZ47,$S$4:$BZ$4,K$4) -> 0 | L47: =SUMIFS($S47:$BZ47,$S$4:$BZ$4,L$4) -> 0 | M47: =SUMIFS($S47:$BZ47,$S$4:$BZ$4,M$4) -> 0 | N47: =SUMIFS($S47:$BZ47,$S$4:$BZ$4,N$4) -> -1224567.7 | R47: =-IF(R$6=$E$9,R35*$E$28,0) -> 0 | S47: =-IF(S$6=$E$9,S35*$E$28,0) -> 0 | T47: =-IF(T$6=$E$9,T35*$E$28,0) -> 0 | U47: =-IF(U$6=$E$9,U35*$E$28,0) -> 0 | V47: =-IF(V$6=$E$9,V35*$E$28,0) -> 0 | W47: =-IF(W$6=$E$9,W35*$E$28,0) -> 0 | X47: =-IF(X$6=$E$9,X35*$E$28,0) -> 0 | Y47: =-IF(Y$6=$E$9,Y35*$E$28,0) -> 0 | ... BZ47: =-IF(BZ$6=$E$9,BZ35*$E$28,0) -> -1224567.7
D48: Balloon Repayment | J48: =SUMIFS($S48:$BZ48,$S$4:$BZ$4,J$4) -> 0 | K48: =SUMIFS($S48:$BZ48,$S$4:$BZ$4,K$4) -> 0 | L48: =SUMIFS($S48:$BZ48,$S$4:$BZ$4,L$4) -> 0 | M48: =SUMIFS($S48:$BZ48,$S$4:$BZ$4,M$4) -> 0 | N48: =SUMIFS($S48:$BZ48,$S$4:$BZ$4,N$4) -> -1.2245677e+08 | R48: =IF(R$6=$E$9,-(R35+R36+R40+R43+R44),0) -> 0 | S48: =IF(S$6=$E$9,-(S35+S36+S40+S43+S44),0) -> 0 | T48: =IF(T$6=$E$9,-(T35+T36+T40+T43+T44),0) -> 0 | U48: =IF(U$6=$E$9,-(U35+U36+U40+U43+U44),0) -> 0 | V48: =IF(V$6=$E$9,-(V35+V36+V40+V43+V44),0) -> 0 | W48: =IF(W$6=$E$9,-(W35+W36+W40+W43+W44),0) -> 0 | X48: =IF(X$6=$E$9,-(X35+X36+X40+X43+X44),0) -> 0 | Y48: =IF(Y$6=$E$9,-(Y35+Y36+Y40+Y43+Y44),0) -> 0 | ... BZ48: =IF(BZ$6=$E$9,-(BZ35+BZ36+BZ40+BZ43+BZ44),0) -> -1.2245677e+08
D49: Closing Balance | J49: {=INDEX($S49:$BZ49,0,MATCH(J$6,$S$6:$BZ$6,0))} -> 1.8775222e+08 | K49: {=INDEX($S49:$BZ49,0,MATCH(K$6,$S$6:$BZ$6,0))} -> 1.7279078e+08 | L49: {=INDEX($S49:$BZ49,0,MATCH(L$6,$S$6:$BZ$6,0))} -> 1.5693807e+08 | M49: {=INDEX($S49:$BZ49,0,MATCH(M$6,$S$6:$BZ$6,0))} -> 1.4017505e+08 | N49: {=INDEX($S49:$BZ49,0,MATCH(N$6,$S$6:$BZ$6,0))} -> 0 | R49: =R35+R36+R40+R43+R44+R48 -> 2.0184459e+08 | S49: =S35+S36+S40+S43+S44+S48 -> 2.0184459e+08 | T49: =T35+T36+T40+T43+T44+T48 -> 2.0184459e+08 | U49: =U35+U36+U40+U43+U44+U48 -> 2.0184459e+08 | V49: =V35+V36+V40+V43+V44+V48 -> 2.0184459e+08 | W49: =W35+W36+W40+W43+W44+W48 -> 1.9488404e+08 | X49: =X35+X36+X40+X43+X44+X48 -> 1.9488404e+08 | Y49: =Y35+Y36+Y40+Y43+Y44+Y48 -> 1.9488404e+08 | ... BZ49: =BZ35+BZ36+BZ40+BZ43+BZ44+BZ48 -> 0
D51: Equity Cashflow | J51: =SUMIFS($S51:$BZ51,$S$4:$BZ$4,J$4) -> -31397764 | K51: =SUMIFS($S51:$BZ51,$S$4:$BZ$4,K$4) -> -31005739 | L51: =SUMIFS($S51:$BZ51,$S$4:$BZ$4,L$4) -> -30559065 | M51: =SUMIFS($S51:$BZ51,$S$4:$BZ$4,M$4) -> -30052726 | N51: =SUMIFS($S51:$BZ51,$S$4:$BZ$4,N$4) -> -1.5319156e+08 | R51: =R36+R37+R39+R42+R44+R47+R48 -> 1.9982615e+08 | S51: =S36+S37+S39+S42+S44+S47+S48 -> -1476156.8 | T51: =T36+T37+T39+T42+T44+T47+T48 -> -1476156.8 | U51: =U36+U37+U39+U42+U44+U47+U48 -> -1476156.8 | V51: =V36+V37+V39+V42+V44+V47+V48 -> -1476156.8 | W51: =W36+W37+W39+W42+W44+W47+W48 -> -8436711.6 | X51: =X36+X37+X39+X42+X44+X47+X48 -> -1425251.9 | Y51: =Y36+Y37+Y39+Y42+Y44+Y47+Y48 -> -1425251.9 | ... BZ51: =BZ36+BZ37+BZ39+BZ42+BZ44+BZ47+BZ48 -> -1.2457691e+08
...

Sheet Portfolio
I2: FY23 | J2: FY24 | K2: FY25 | L2: LTM | W2: {=INDEX(Index_Tab!$G$4:$K$4,MATCH(1,(W$4>=Index_Tab!$G$5:$K$5)*(W$4<=Index_Tab!$G$17:$K$17),0))} -> FY27E | X2: {=INDEX(Index_Tab!$G$4:$K$4,MATCH(1,(X$4>=Index_Tab!$G$5:$K$5)*(X$4<=Index_Tab!$G$17:$K$17),0))} -> FY27E | Y2: {=INDEX(Index_Tab!$G$4:$K$4,MATCH(1,(Y$4>=Index_Tab!$G$5:$K$5)*(Y$4<=Index_Tab!$G$17:$K$17),0))} -> FY27E | Z2: {=INDEX(Index_Tab!$G$4:$K$4,MATCH(1,(Z$4>=Index_Tab!$G$5:$K$5)*(Z$4<=Index_Tab!$G$17:$K$17),0))} -> FY27E | AA2: {=INDEX(Index_Tab!$G$4:$K$4,MATCH(1,(AA$4>=Index_Tab!$G$5:$K$5)*(AA$4<=Index_Tab!$G$17:$K$17),0))} -> FY27E | AB2: {=INDEX(Index_Tab!$G$4:$K$4,MATCH(1,(AB$4>=Index_Tab!$G$5:$K$5)*(AB$4<=Index_Tab!$G$17:$K$17),0))} -> FY27E | AC2: {=INDEX(Index_Tab!$G$4:$K$4,MATCH(1,(AC$4>=Index_Tab!$G$5:$K$5)*(AC$4<=Index_Tab!$G$17:$K$17),0))} -> FY27E | AD2: {=INDEX(Index_Tab!$G$4:$K$4,MATCH(1,(AD$4>=Index_Tab!$G$5:$K$5)*(AD$4<=Index_Tab!$G$17:$K$17),0))} -> FY27E | ... CD2: {=INDEX(Index_Tab!$G$4:$K$4,MATCH(1,(CD$4>=Index_Tab!$G$5:$K$5)*(CD$4<=Index_Tab!$G$17:$K$17),0))} -> FY31E
I3: FY23A | J3: FY24A | K3: FY25A | L3: FY26 P4 LTM | N3: ='Detailed Assumptions'!$E$17 -> FY26E | O3: ='Detailed Assumptions'!$F$17 -> FY27E | P3: ='Detailed Assumptions'!$G$17 -> FY28E | Q3: ='Detailed Assumptions'!$H$17 -> FY29E | R3: ='Detailed Assumptions'!$I$17 -> FY30E | S3: ='Detailed Assumptions'!$J$17 -> FY31E | U3: =N3&"-"&S3 -> FY26E-FY31E | W3: ='Detailed Assumptions'!$E$12 -> 46296 | X3: =W4+1 -> 46327 | Y3: =X4+1 -> 46357 | Z3: =Y4+1 -> 46388 | AA3: =Z4+1 -> 46419 | AB3: =AA4+1 -> 46447 | AC3: =AB4+1 -> 46478 | AD3: =AC4+1 -> 46508 | AE3: =AD4+1 -> 46539 | ... CD3: =CC4+1 -> 48092
I4: 45199 | J4: =EDATE(I4,12) -> 45565 | K4: =EDATE(J4,12) -> 45930 | L4: 46040 | N4: ='Detailed Assumptions'!$E$12-1 -> 46295 | O4: =EOMONTH(N4,12) -> 46660 | P4: =EOMONTH(O4,12) -> 47026 | Q4: =EOMONTH(P4,12) -> 47391 | R4: =EOMONTH(Q4,12) -> 47756 | S4: =EOMONTH(R4,12) -> 48121 | U4: CAGR | W4: =EOMONTH(W3,0) -> 46326 | X4: =EOMONTH(X3,0) -> 46356 | Y4: =EOMONTH(Y3,0) -> 46387 | Z4: =EOMONTH(Z3,0) -> 46418 | AA4: =EOMONTH(AA3,0) -> 46446 | AB4: =EOMONTH(AB3,0) -> 46477 | AC4: =EOMONTH(AC3,0) -> 46507 | AD4: =EOMONTH(AD3,0) -> 46538 | ... CD4: =EOMONTH(CD3,0) -> 48121
C7: X | E7: Consolidated Output
E9: Total no. of pubs within sub-portfolio | I9: =$N$9 -> 308 | J9: =$N$9 -> 308 | K9: =$N$9 -> 308 | L9: =$N$9 -> 308 | N9: ='Value Segment'!I9+'Mid-Market Segment'!I9+'Upper Mid-Market Segment'!I9+'Premium Segment'!I9+'Closures Overlay'!I9+'Disposals Overlay'!I9 -> 308 | O9: =INDEX($W9:$CD9,MATCH(O$4,$W$4:$CD$4,0)) -> 292 | P9: =INDEX($W9:$CD9,MATCH(P$4,$W$4:$CD$4,0)) -> 276 | Q9: =INDEX($W9:$CD9,MATCH(Q$4,$W$4:$CD$4,0)) -> 260 | R9: =INDEX($W9:$CD9,MATCH(R$4,$W$4:$CD$4,0)) -> 244 | S9: =INDEX($W9:$CD9,MATCH(S$4,$W$4:$CD$4,0)) -> 228 | W9: ='Value Segment'!R9+'Mid-Market Segment'!R9+'Upper Mid-Market Segment'!R9+'Premium Segment'!R9+'Closures Overlay'!R9+'Disposals Overlay'!R9 -> 308 | X9: ='Value Segment'!S9+'Mid-Market Segment'!S9+'Upper Mid-Market Segment'!S9+'Premium Segment'!S9+'Closures Overlay'!S9+'Disposals Overlay'!S9 -> 308 | Y9: ='Value Segment'!T9+'Mid-Market Segment'!T9+'Upper Mid-Market Segment'!T9+'Premium Segment'!T9+'Closures Overlay'!T9+'Disposals Overlay'!T9 -> 308 | Z9: ='Value Segment'!U9+'Mid-Market Segment'!U9+'Upper Mid-Market Segment'!U9+'Premium Segment'!U9+'Closures Overlay'!U9+'Disposals Overlay'!U9 -> 308 | AA9: ='Value Segment'!V9+'Mid-Market Segment'!V9+'Upper Mid-Market Segment'!V9+'Premium Segment'!V9+'Closures Overlay'!V9+'Disposals Overlay'!V9 -> 308 | AB9: ='Value Segment'!W9+'Mid-Market Segment'!W9+'Upper Mid-Market Segment'!W9+'Premium Segment'!W9+'Closures Overlay'!W9+'Disposals Overlay'!W9 -> 300 | AC9: ='Value Segment'!X9+'Mid-Market Segment'!X9+'Upper Mid-Market Segment'!X9+'Premium Segment'!X9+'Closures Overlay'!X9+'Disposals Overlay'!X9 -> 300 | AD9: ='Value Segment'!Y9+'Mid-Market Segment'!Y9+'Upper Mid-Market Segment'!Y9+'Premium Segment'!Y9+'Closures Overlay'!Y9+'Disposals Overlay'!Y9 -> 300 | ... CD9: ='Value Segment'!BY9+'Mid-Market Segment'!BY9+'Upper Mid-Market Segment'!BY9+'Premium Segment'!BY9+'Closures Overlay'!BY9+'Disposals Overlay'!BY9 -> 228
E11: Total no. of pubs within sub-portfolio | I11: =I9 -> 308 | J11: =J9 -> 308 | K11: =K9 -> 308 | L11: =L9 -> 308 | N11: =N9 -> 308 | O11: =INDEX($W11:$CD11,MATCH(O$4,$W$4:$CD$4,0)) -> 292 | P11: =INDEX($W11:$CD11,MATCH(P$4,$W$4:$CD$4,0)) -> 276 | Q11: =INDEX($W11:$CD11,MATCH(Q$4,$W$4:$CD$4,0)) -> 260 | R11: =INDEX($W11:$CD11,MATCH(R$4,$W$4:$CD$4,0)) -> 244 | S11: =INDEX($W11:$CD11,MATCH(S$4,$W$4:$CD$4,0)) -> 228 | W11: ='Value Segment'!R11+'Mid-Market Segment'!R11+'Upper Mid-Market Segment'!R11+'Premium Segment'!R11+'Closures Overlay'!R11+'Disposals Overlay'!R11 -> 308 | X11: ='Value Segment'!S11+'Mid-Market Segment'!S11+'Upper Mid-Market Segment'!S11+'Premium Segment'!S11+'Closures Overlay'!S11+'Disposals Overlay'!S11 -> 308 | Y11: ='Value Segment'!T11+'Mid-Market Segment'!T11+'Upper Mid-Market Segment'!T11+'Premium Segment'!T11+'Closures Overlay'!T11+'Disposals Overlay'!T11 -> 308 | Z11: ='Value Segment'!U11+'Mid-Market Segment'!U11+'Upper Mid-Market Segment'!U11+'Premium Segment'!U11+'Closures Overlay'!U11+'Disposals Overlay'!U11 -> 308 | AA11: ='Value Segment'!V11+'Mid-Market Segment'!V11+'Upper Mid-Market Segment'!V11+'Premium Segment'!V11+'Closures Overlay'!V11+'Disposals Overlay'!V11 -> 308 | AB11: ='Value Segment'!W11+'Mid-Market Segment'!W11+'Upper Mid-Market Segment'!W11+'Premium Segment'!W11+'Closures Overlay'!W11+'Disposals Overlay'!W11 -> 300 | AC11: ='Value Segment'!X11+'Mid-Market Segment'!X11+'Upper Mid-Market Segment'!X11+'Premium Segment'!X11+'Closures Overlay'!X11+'Disposals Overlay'!X11 -> 300 | AD11: ='Value Segment'!Y11+'Mid-Market Segment'!Y11+'Upper Mid-Market Segment'!Y11+'Premium Segment'!Y11+'Closures Overlay'!Y11+'Disposals Overlay'!Y11 -> 300 | ... CD11: ='Value Segment'!BY11+'Mid-Market Segment'!BY11+'Upper Mid-Market Segment'!BY11+'Premium Segment'!BY11+'Closures Overlay'!BY11+'Disposals Overlay'!BY11 -> 228
E12: of which open | I12: 0 | J12: 0 | K12: 0 | L12: 0 | N12: =N11-N13 -> 298 | O12: =INDEX($W12:$CD12,MATCH(O$4,$W$4:$CD$4,0)) -> 282 | P12: =INDEX($W12:$CD12,MATCH(P$4,$W$4:$CD$4,0)) -> 266 | Q12: =INDEX($W12:$CD12,MATCH(Q$4,$W$4:$CD$4,0)) -> 250 | R12: =INDEX($W12:$CD12,MATCH(R$4,$W$4:$CD$4,0)) -> 234 | S12: =INDEX($W12:$CD12,MATCH(S$4,$W$4:$CD$4,0)) -> 218 | W12: =W11-W13 -> 298 | X12: =X11-X13 -> 298 | Y12: =Y11-Y13 -> 298 | Z12: =Z11-Z13 -> 298 | AA12: =AA11-AA13 -> 298 | AB12: =AB11-AB13 -> 290 | AC12: =AC11-AC13 -> 290 | AD12: =AD11-AD13 -> 290 | ... CD12: =CD11-CD13 -> 218
E13: of which closed | I13: 0 | J13: 0 | K13: 0 | L13: 0 | N13: ='Value Segment'!I13+'Mid-Market Segment'!I13+'Upper Mid-Market Segment'!I13+'Premium Segment'!I13+'Closures Overlay'!I13+'Disposals Overlay'!I13 -> 10 | O13: =INDEX($W13:$CD13,MATCH(O$4,$W$4:$CD$4,0)) -> 10 | P13: =INDEX($W13:$CD13,MATCH(P$4,$W$4:$CD$4,0)) -> 10 | Q13: =INDEX($W13:$CD13,MATCH(Q$4,$W$4:$CD$4,0)) -> 10 | R13: =INDEX($W13:$CD13,MATCH(R$4,$W$4:$CD$4,0)) -> 10 | S13: =INDEX($W13:$CD13,MATCH(S$4,$W$4:$CD$4,0)) -> 10 | W13: ='Value Segment'!R13+'Mid-Market Segment'!R13+'Upper Mid-Market Segment'!R13+'Premium Segment'!R13+'Closures Overlay'!R13+'Disposals Overlay'!R13 -> 10 | X13: ='Value Segment'!S13+'Mid-Market Segment'!S13+'Upper Mid-Market Segment'!S13+'Premium Segment'!S13+'Closures Overlay'!S13+'Disposals Overlay'!S13 -> 10 | Y13: ='Value Segment'!T13+'Mid-Market Segment'!T13+'Upper Mid-Market Segment'!T13+'Premium Segment'!T13+'Closures Overlay'!T13+'Disposals Overlay'!T13 -> 10 | Z13: ='Value Segment'!U13+'Mid-Market Segment'!U13+'Upper Mid-Market Segment'!U13+'Premium Segment'!U13+'Closures Overlay'!U13+'Disposals Overlay'!U13 -> 10 | AA13: ='Value Segment'!V13+'Mid-Market Segment'!V13+'Upper Mid-Market Segment'!V13+'Premium Segment'!V13+'Closures Overlay'!V13+'Disposals Overlay'!V13 -> 10 | AB13: ='Value Segment'!W13+'Mid-Market Segment'!W13+'Upper Mid-Market Segment'!W13+'Premium Segment'!W13+'Closures Overlay'!W13+'Disposals Overlay'!W13 -> 10 | AC13: ='Value Segment'!X13+'Mid-Market Segment'!X13+'Upper Mid-Market Segment'!X13+'Premium Segment'!X13+'Closures Overlay'!X13+'Disposals Overlay'!X13 -> 10 | AD13: ='Value Segment'!Y13+'Mid-Market Segment'!Y13+'Upper Mid-Market Segment'!Y13+'Premium Segment'!Y13+'Closures Overlay'!Y13+'Disposals Overlay'!Y13 -> 10 | ... CD13: ='Value Segment'!BY13+'Mid-Market Segment'!BY13+'Upper Mid-Market Segment'!BY13+'Premium Segment'!BY13+'Closures Overlay'!BY13+'Disposals Overlay'!BY13 -> 10
E15: Total no. of pubs within sub-portfolio | I15: =I11 -> 308 | J15: =J11 -> 308 | K15: =K11 -> 308 | L15: =L11 -> 308 | N15: ='Value Segment'!I15+'Mid-Market Segment'!I15+'Upper Mid-Market Segment'!I15+'Premium Segment'!I15+'Closures Overlay'!I15+'Disposals Overlay'!I15 -> 308 | O15: =INDEX($W15:$CD15,MATCH(O$4,$W$4:$CD$4,0)) -> 292 | P15: =INDEX($W15:$CD15,MATCH(P$4,$W$4:$CD$4,0)) -> 276 | Q15: =INDEX($W15:$CD15,MATCH(Q$4,$W$4:$CD$4,0)) -> 260 | R15: =INDEX($W15:$CD15,MATCH(R$4,$W$4:$CD$4,0)) -> 244 | S15: =INDEX($W15:$CD15,MATCH(S$4,$W$4:$CD$4,0)) -> 228 | W15: ='Value Segment'!R15+'Mid-Market Segment'!R15+'Upper Mid-Market Segment'!R15+'Premium Segment'!R15+'Closures Overlay'!R15+'Disposals Overlay'!R15 -> 308 | X15: ='Value Segment'!S15+'Mid-Market Segment'!S15+'Upper Mid-Market Segment'!S15+'Premium Segment'!S15+'Closures Overlay'!S15+'Disposals Overlay'!S15 -> 308 | Y15: ='Value Segment'!T15+'Mid-Market Segment'!T15+'Upper Mid-Market Segment'!T15+'Premium Segment'!T15+'Closures Overlay'!T15+'Disposals Overlay'!T15 -> 308 | Z15: ='Value Segment'!U15+'Mid-Market Segment'!U15+'Upper Mid-Market Segment'!U15+'Premium Segment'!U15+'Closures Overlay'!U15+'Disposals Overlay'!U15 -> 308 | AA15: ='Value Segment'!V15+'Mid-Market Segment'!V15+'Upper Mid-Market Segment'!V15+'Premium Segment'!V15+'Closures Overlay'!V15+'Disposals Overlay'!V15 -> 308 | AB15: ='Value Segment'!W15+'Mid-Market Segment'!W15+'Upper Mid-Market Segment'!W15+'Premium Segment'!W15+'Closures Overlay'!W15+'Disposals Overlay'!W15 -> 300 | AC15: ='Value Segment'!X15+'Mid-Market Segment'!X15+'Upper Mid-Market Segment'!X15+'Premium Segment'!X15+'Closures Overlay'!X15+'Disposals Overlay'!X15 -> 300 | AD15: ='Value Segment'!Y15+'Mid-Market Segment'!Y15+'Upper Mid-Market Segment'!Y15+'Premium Segment'!Y15+'Closures Overlay'!Y15+'Disposals Overlay'!Y15 -> 300 | ... CD15: ='Value Segment'!BY15+'Mid-Market Segment'!BY15+'Upper Mid-Market Segment'!BY15+'Premium Segment'!BY15+'Closures Overlay'!BY15+'Disposals Overlay'!BY15 -> 228
