Workbook

Sheet Inputs
A1: Roehampton Sports Ground Estate — underwrite model
A2: Bruce Gillingham Pollard with Related · 17 October 2026 · Blue cells are inputs and match the BGP defaults on the appraisal page; everything else is a formula.
A4: The bid
A5: Purchase price, whole estate | B5: 18 | C5: £m | D5: Base case; no guide published. The appraisal page gives the bid for 15% on cost with the residential placeholder at £7m. Use Goal Seek on Outputs, Profit on cost, by changing this cell.
A6: Purchaser's costs | B6: 0.068 | C6: % | D6: SDLT, legals, agents
A7: Hold period | B7: 3 | C7: years | D7: Exit at the end of this year (1 to 10)
A8: Target profit on cost | B8: 0.15 | C8: %
A9: Third Space
A10: Area let | B10: 60142 | C10: sq ft GIA | D10: Sports Club 32,377 + permanent Pavilion 27,765; squash excluded; Knight Frank schedule and Principal Plans GIA agree
A11: Rent per sq ft GIA | B11: 30 | C11: £
A12: Rent free | B12: 2 | C12: years
A13: Capital contribution | B13: 1 | C13: years' rent
A14: CPI assumption | B14: 0.03 | C14: % pa | D14: Reviews 5-yearly, compounded, capped at 3% pa
A15: Landlord's works | B15: 0 | C15: £ psf | D15: Nil: Third Space fit out from the capital contribution and nothing more is spent on the leisure side
A16: Fees and contingency on works | B16: 0.15 | C16: %
A17: Exit yield, Third Space | B17: 0.075 | C17: % | D17: 20 years, indexed
A18: All England Club
A19: New rent from completion | B19: 100000 | C19: £ pa | D19: All England Club rent from completion; surrender and regrant complete on the day of purchase
A20: Surrender premium to the Club | B20: 0 | C20: £
A21: Exit yield, grounds | B21: 0.07 | C21: %
A22: Other lots
A23: National Tennis Centre reversion at exit | B23: 0.5 | C23: £m | D23: Peppercorn to 2129
A24: Year the residential value is taken in | B24: 3 | C24: year | D24: Year the Grange value is taken in: 0 = on completion; otherwise end of that year. Everything is sold at once at the end of the hold.
A25: Grange holding cost until sold | B25: 0 | C25: £ pa | D25: Grange holding cost until sold: 0 while Related's underwrite carries the conversion costs and value; c. £1,000,000 pa if held empty
A26: The Grange and cottages, exit valuation | B26: 7 | C26: £m | D26: BGP's exit valuation of The Grange and the cottages together, sold with everything else at the end of the hold; Related are underwriting the conversion
A27: Debt
A28: Loan to value | B28: 0.5 | C28: % | D28: One loan on purchase, sized on the valuation after the lettings; no refinance
A29: All-in interest rate | B29: 0.09 | C29: %
A30: Arrangement and exit fees | B30: 0.015 | C30: % of the loan
A32: Derived
A33: Third Space headline rent, £ pa | B33: =Inputs!$B$10*Inputs!$B$11 -> 1804260
A34: Landlord's works, £ | B34: =Inputs!$B$10*Inputs!$B$15 -> 0
A35: Fees and contingency, £ | B35: =B34*Inputs!$B$16 -> 0
A36: Capital contribution, £ | B36: =B33*Inputs!$B$13 -> 1804260
A37: Rent free cost, £ | B37: =B33*Inputs!$B$12 -> 3608520
A38: Purchase price, £ | B38: =Inputs!$B$5*1000000 -> 18000000
A39: Grange price, £ | B39: =Inputs!$B$26*1000000 -> 7000000
A40: NTC reversion, £ | B40: =Inputs!$B$23*1000000 -> 500000
A41: Rent at exit, Third Space, £ pa | B41: =B33*(1+Inputs!$B$14)^(5*INT((Inputs!$B$7-1)/5)) -> 1804260
A42: Rent free a purchaser still bears at exit, years | B42: =MAX(0,Inputs!$B$12-Inputs!$B$7) -> 0
...

Sheet Cash flow
A1: Annual cash flow, £
A2: Completion January 2027 (year 0): purchase, Third Space lease, capital contribution and the Club's surrender and regrant all on the same day. Nothing more spent on the leisure side; everything sold as one lot at the end of the hold year. Rows beyond the hold year are zero.
A4: Year | B4: Period | C4: Active | D4: Club rent | E4: Third Space rent | F4: Capital receipts | G4: Purchase, works and incentives | H4: Grange holding | I4: Exit proceeds | J4: Net before debt | K4: Funding need | L4: Debt drawn | M4: Opening balance | N4: Interest | O4: Fees | P4: Repayment | Q4: Closing balance | R4: Debt cash flow | S4: Equity cash flow | T4: Cumulative equity
A5: 0 | B5: =IF(A5=0,"Completion",TEXT(2026+A5,"0")&IF(A5=Inputs!$B$7," and exit","")) -> Completion | C5: =IF(A5<=Inputs!$B$7,1,0) -> 1 | D5: =C5*IF(A5=0,0,Inputs!$B$19) -> 0 | E5: =C5*IF(A5<1,0,IF(A5<=Inputs!$B$12,0,IF(A5-1<Inputs!$B$12,A5-Inputs!$B$12,1)*Inputs!$B$33*(1+Inputs!$B$14)^(5*INT((A5-1)/5)))) -> 0 | F5: =C5*(IF(A5=0,IF(Inputs!$B$24=0,Inputs!$B$39,0),0)+IF(AND(Inputs!$B$24>0,A5=Inputs!$B$24),Inputs!$B$39,0)) -> 0 | G5: =-C5*(IF(A5=0,Inputs!$B$38*(1+Inputs!$B$6)+Inputs!$B$36+Inputs!$B$20,0)+IF(A5=1,Inputs!$B$34+Inputs!$B$35,0)) -> -21028260 | H5: =-C5*IF(AND(Inputs!$B$24>0,A5>=1,A5<=Inputs!$B$24),Inputs!$B$25,0) -> 0 | I5: =IF(A5=Inputs!$B$7,Inputs!$B$43+Inputs!$B$44+Inputs!$B$40,0) -> 0 | J5: =SUM(D5:I5) -> -21028260 | K5: =-G5-F5 -> 21028260 | L5: =IF(A5=0,Inputs!$B$47,0) -> 15681354 | M5: =0 -> 0 | N5: =M5*Inputs!$B$29 -> 0 | O5: =L5*Inputs!$B$30 -> 235220.3 | P5: =IF(K5<0,MIN(M5+L5,-K5),0)+IF(A5=Inputs!$B$7,M5+L5-IF(K5<0,MIN(M5+L5,-K5),0),0) -> 0 | Q5: =M5+L5-P5 -> 15681354 | R5: =L5-N5-P5-O5 -> 15446133 | S5: =J5+R5 -> -5582126.6 | T5: =S5 -> -5582126.6
A6: 1 | B6: =IF(A6=0,"Completion",TEXT(2026+A6,"0")&IF(A6=Inputs!$B$7," and exit","")) -> 2027 | C6: =IF(A6<=Inputs!$B$7,1,0) -> 1 | D6: =C6*IF(A6=0,0,Inputs!$B$19) -> 100000 | E6: =C6*IF(A6<1,0,IF(A6<=Inputs!$B$12,0,IF(A6-1<Inputs!$B$12,A6-Inputs!$B$12,1)*Inputs!$B$33*(1+Inputs!$B$14)^(5*INT((A6-1)/5)))) -> 0 | F6: =C6*(IF(A6=0,IF(Inputs!$B$24=0,Inputs!$B$39,0),0)+IF(AND(Inputs!$B$24>0,A6=Inputs!$B$24),Inputs!$B$39,0)) -> 0 | G6: =-C6*(IF(A6=0,Inputs!$B$38*(1+Inputs!$B$6)+Inputs!$B$36+Inputs!$B$20,0)+IF(A6=1,Inputs!$B$34+Inputs!$B$35,0)) -> 0 | H6: =-C6*IF(AND(Inputs!$B$24>0,A6>=1,A6<=Inputs!$B$24),Inputs!$B$25,0) -> 0 | I6: =IF(A6=Inputs!$B$7,Inputs!$B$43+Inputs!$B$44+Inputs!$B$40,0) -> 0 | J6: =SUM(D6:I6) -> 100000 | K6: =-G6-F6 -> 0 | L6: =IF(A6=0,Inputs!$B$47,0) -> 0 | M6: =Q5 -> 15681354 | N6: =M6*Inputs!$B$29 -> 1411321.8 | O6: =L6*Inputs!$B$30 -> 0 | P6: =IF(K6<0,MIN(M6+L6,-K6),0)+IF(A6=Inputs!$B$7,M6+L6-IF(K6<0,MIN(M6+L6,-K6),0),0) -> 0 | Q6: =M6+L6-P6 -> 15681354 | R6: =L6-N6-P6-O6 -> -1411321.8 | S6: =J6+R6 -> -1311321.8 | T6: =T5+S6 -> -6893448.5
A7: 2 | B7: =IF(A7=0,"Completion",TEXT(2026+A7,"0")&IF(A7=Inputs!$B$7," and exit","")) -> 2028 | C7: =IF(A7<=Inputs!$B$7,1,0) -> 1 | D7: =C7*IF(A7=0,0,Inputs!$B$19) -> 100000 | E7: =C7*IF(A7<1,0,IF(A7<=Inputs!$B$12,0,IF(A7-1<Inputs!$B$12,A7-Inputs!$B$12,1)*Inputs!$B$33*(1+Inputs!$B$14)^(5*INT((A7-1)/5)))) -> 0 | F7: =C7*(IF(A7=0,IF(Inputs!$B$24=0,Inputs!$B$39,0),0)+IF(AND(Inputs!$B$24>0,A7=Inputs!$B$24),Inputs!$B$39,0)) -> 0 | G7: =-C7*(IF(A7=0,Inputs!$B$38*(1+Inputs!$B$6)+Inputs!$B$36+Inputs!$B$20,0)+IF(A7=1,Inputs!$B$34+Inputs!$B$35,0)) -> 0 | H7: =-C7*IF(AND(Inputs!$B$24>0,A7>=1,A7<=Inputs!$B$24),Inputs!$B$25,0) -> 0 | I7: =IF(A7=Inputs!$B$7,Inputs!$B$43+Inputs!$B$44+Inputs!$B$40,0) -> 0 | J7: =SUM(D7:I7) -> 100000 | K7: =-G7-F7 -> 0 | L7: =IF(A7=0,Inputs!$B$47,0) -> 0 | M7: =Q6 -> 15681354 | N7: =M7*Inputs!$B$29 -> 1411321.8 | O7: =L7*Inputs!$B$30 -> 0 | P7: =IF(K7<0,MIN(M7+L7,-K7),0)+IF(A7=Inputs!$B$7,M7+L7-IF(K7<0,MIN(M7+L7,-K7),0),0) -> 0 | Q7: =M7+L7-P7 -> 15681354 | R7: =L7-N7-P7-O7 -> -1411321.8 | S7: =J7+R7 -> -1311321.8 | T7: =T6+S7 -> -8204770.3
A8: 3 | B8: =IF(A8=0,"Completion",TEXT(2026+A8,"0")&IF(A8=Inputs!$B$7," and exit","")) -> 2029 and exit | C8: =IF(A8<=Inputs!$B$7,1,0) -> 1 | D8: =C8*IF(A8=0,0,Inputs!$B$19) -> 100000 | E8: =C8*IF(A8<1,0,IF(A8<=Inputs!$B$12,0,IF(A8-1<Inputs!$B$12,A8-Inputs!$B$12,1)*Inputs!$B$33*(1+Inputs!$B$14)^(5*INT((A8-1)/5)))) -> 1804260 | F8: =C8*(IF(A8=0,IF(Inputs!$B$24=0,Inputs!$B$39,0),0)+IF(AND(Inputs!$B$24>0,A8=Inputs!$B$24),Inputs!$B$39,0)) -> 7000000 | G8: =-C8*(IF(A8=0,Inputs!$B$38*(1+Inputs!$B$6)+Inputs!$B$36+Inputs!$B$20,0)+IF(A8=1,Inputs!$B$34+Inputs!$B$35,0)) -> 0 | H8: =-C8*IF(AND(Inputs!$B$24>0,A8>=1,A8<=Inputs!$B$24),Inputs!$B$25,0) -> 0 | I8: =IF(A8=Inputs!$B$7,Inputs!$B$43+Inputs!$B$44+Inputs!$B$40,0) -> 24362707 | J8: =SUM(D8:I8) -> 33266967 | K8: =-G8-F8 -> -7000000 | L8: =IF(A8=0,Inputs!$B$47,0) -> 0 | M8: =Q7 -> 15681354 | N8: =M8*Inputs!$B$29 -> 1411321.8 | O8: =L8*Inputs!$B$30 -> 0 | P8: =IF(K8<0,MIN(M8+L8,-K8),0)+IF(A8=Inputs!$B$7,M8+L8-IF(K8<0,MIN(M8+L8,-K8),0),0) -> 15681354 | Q8: =M8+L8-P8 -> 0 | R8: =L8-N8-P8-O8 -> -17092675 | S8: =J8+R8 -> 16174292 | T8: =T7+S8 -> 7969521.5
A9: 4 | B9: =IF(A9=0,"Completion",TEXT(2026+A9,"0")&IF(A9=Inputs!$B$7," and exit","")) -> 2030 | C9: =IF(A9<=Inputs!$B$7,1,0) -> 0 | D9: =C9*IF(A9=0,0,Inputs!$B$19) -> 0 | E9: =C9*IF(A9<1,0,IF(A9<=Inputs!$B$12,0,IF(A9-1<Inputs!$B$12,A9-Inputs!$B$12,1)*Inputs!$B$33*(1+Inputs!$B$14)^(5*INT((A9-1)/5)))) -> 0 | F9: =C9*(IF(A9=0,IF(Inputs!$B$24=0,Inputs!$B$39,0),0)+IF(AND(Inputs!$B$24>0,A9=Inputs!$B$24),Inputs!$B$39,0)) -> 0 | G9: =-C9*(IF(A9=0,Inputs!$B$38*(1+Inputs!$B$6)+Inputs!$B$36+Inputs!$B$20,0)+IF(A9=1,Inputs!$B$34+Inputs!$B$35,0)) -> 0 | H9: =-C9*IF(AND(Inputs!$B$24>0,A9>=1,A9<=Inputs!$B$24),Inputs!$B$25,0) -> 0 | I9: =IF(A9=Inputs!$B$7,Inputs!$B$43+Inputs!$B$44+Inputs!$B$40,0) -> 0 | J9: =SUM(D9:I9) -> 0 | K9: =-G9-F9 -> 0 | L9: =IF(A9=0,Inputs!$B$47,0) -> 0 | M9: =Q8 -> 0 | N9: =M9*Inputs!$B$29 -> 0 | O9: =L9*Inputs!$B$30 -> 0 | P9: =IF(K9<0,MIN(M9+L9,-K9),0)+IF(A9=Inputs!$B$7,M9+L9-IF(K9<0,MIN(M9+L9,-K9),0),0) -> 0 | Q9: =M9+L9-P9 -> 0 | R9: =L9-N9-P9-O9 -> 0 | S9: =J9+R9 -> 0 | T9: =T8+S9 -> 7969521.5
A10: 5 | B10: =IF(A10=0,"Completion",TEXT(2026+A10,"0")&IF(A10=Inputs!$B$7," and exit","")) -> 2031 | C10: =IF(A10<=Inputs!$B$7,1,0) -> 0 | D10: =C10*IF(A10=0,0,Inputs!$B$19) -> 0 | E10: =C10*IF(A10<1,0,IF(A10<=Inputs!$B$12,0,IF(A10-1<Inputs!$B$12,A10-Inputs!$B$12,1)*Inputs!$B$33*(1+Inputs!$B$14)^(5*INT((A10-1)/5)))) -> 0 | F10: =C10*(IF(A10=0,IF(Inputs!$B$24=0,Inputs!$B$39,0),0)+IF(AND(Inputs!$B$24>0,A10=Inputs!$B$24),Inputs!$B$39,0)) -> 0 | G10: =-C10*(IF(A10=0,Inputs!$B$38*(1+Inputs!$B$6)+Inputs!$B$36+Inputs!$B$20,0)+IF(A10=1,Inputs!$B$34+Inputs!$B$35,0)) -> 0 | H10: =-C10*IF(AND(Inputs!$B$24>0,A10>=1,A10<=Inputs!$B$24),Inputs!$B$25,0) -> 0 | I10: =IF(A10=Inputs!$B$7,Inputs!$B$43+Inputs!$B$44+Inputs!$B$40,0) -> 0 | J10: =SUM(D10:I10) -> 0 | K10: =-G10-F10 -> 0 | L10: =IF(A10=0,Inputs!$B$47,0) -> 0 | M10: =Q9 -> 0 | N10: =M10*Inputs!$B$29 -> 0 | O10: =L10*Inputs!$B$30 -> 0 | P10: =IF(K10<0,MIN(M10+L10,-K10),0)+IF(A10=Inputs!$B$7,M10+L10-IF(K10<0,MIN(M10+L10,-K10),0),0) -> 0 | Q10: =M10+L10-P10 -> 0 | R10: =L10-N10-P10-O10 -> 0 | S10: =J10+R10 -> 0 | T10: =T9+S10 -> 7969521.5
A11: 6 | B11: =IF(A11=0,"Completion",TEXT(2026+A11,"0")&IF(A11=Inputs!$B$7," and exit","")) -> 2032 | C11: =IF(A11<=Inputs!$B$7,1,0) -> 0 | D11: =C11*IF(A11=0,0,Inputs!$B$19) -> 0 | E11: =C11*IF(A11<1,0,IF(A11<=Inputs!$B$12,0,IF(A11-1<Inputs!$B$12,A11-Inputs!$B$12,1)*Inputs!$B$33*(1+Inputs!$B$14)^(5*INT((A11-1)/5)))) -> 0 | F11: =C11*(IF(A11=0,IF(Inputs!$B$24=0,Inputs!$B$39,0),0)+IF(AND(Inputs!$B$24>0,A11=Inputs!$B$24),Inputs!$B$39,0)) -> 0 | G11: =-C11*(IF(A11=0,Inputs!$B$38*(1+Inputs!$B$6)+Inputs!$B$36+Inputs!$B$20,0)+IF(A11=1,Inputs!$B$34+Inputs!$B$35,0)) -> 0 | H11: =-C11*IF(AND(Inputs!$B$24>0,A11>=1,A11<=Inputs!$B$24),Inputs!$B$25,0) -> 0 | I11: =IF(A11=Inputs!$B$7,Inputs!$B$43+Inputs!$B$44+Inputs!$B$40,0) -> 0 | J11: =SUM(D11:I11) -> 0 | K11: =-G11-F11 -> 0 | L11: =IF(A11=0,Inputs!$B$47,0) -> 0 | M11: =Q10 -> 0 | N11: =M11*Inputs!$B$29 -> 0 | O11: =L11*Inputs!$B$30 -> 0 | P11: =IF(K11<0,MIN(M11+L11,-K11),0)+IF(A11=Inputs!$B$7,M11+L11-IF(K11<0,MIN(M11+L11,-K11),0),0) -> 0 | Q11: =M11+L11-P11 -> 0 | R11: =L11-N11-P11-O11 -> 0 | S11: =J11+R11 -> 0 | T11: =T10+S11 -> 7969521.5
A12: 7 | B12: =IF(A12=0,"Completion",TEXT(2026+A12,"0")&IF(A12=Inputs!$B$7," and exit","")) -> 2033 | C12: =IF(A12<=Inputs!$B$7,1,0) -> 0 | D12: =C12*IF(A12=0,0,Inputs!$B$19) -> 0 | E12: =C12*IF(A12<1,0,IF(A12<=Inputs!$B$12,0,IF(A12-1<Inputs!$B$12,A12-Inputs!$B$12,1)*Inputs!$B$33*(1+Inputs!$B$14)^(5*INT((A12-1)/5)))) -> 0 | F12: =C12*(IF(A12=0,IF(Inputs!$B$24=0,Inputs!$B$39,0),0)+IF(AND(Inputs!$B$24>0,A12=Inputs!$B$24),Inputs!$B$39,0)) -> 0 | G12: =-C12*(IF(A12=0,Inputs!$B$38*(1+Inputs!$B$6)+Inputs!$B$36+Inputs!$B$20,0)+IF(A12=1,Inputs!$B$34+Inputs!$B$35,0)) -> 0 | H12: =-C12*IF(AND(Inputs!$B$24>0,A12>=1,A12<=Inputs!$B$24),Inputs!$B$25,0) -> 0 | I12: =IF(A12=Inputs!$B$7,Inputs!$B$43+Inputs!$B$44+Inputs!$B$40,0) -> 0 | J12: =SUM(D12:I12) -> 0 | K12: =-G12-F12 -> 0 | L12: =IF(A12=0,Inputs!$B$47,0) -> 0 | M12: =Q11 -> 0 | N12: =M12*Inputs!$B$29 -> 0 | O12: =L12*Inputs!$B$30 -> 0 | P12: =IF(K12<0,MIN(M12+L12,-K12),0)+IF(A12=Inputs!$B$7,M12+L12-IF(K12<0,MIN(M12+L12,-K12),0),0) -> 0 | Q12: =M12+L12-P12 -> 0 | R12: =L12-N12-P12-O12 -> 0 | S12: =J12+R12 -> 0 | T12: =T11+S12 -> 7969521.5
A13: 8 | B13: =IF(A13=0,"Completion",TEXT(2026+A13,"0")&IF(A13=Inputs!$B$7," and exit","")) -> 2034 | C13: =IF(A13<=Inputs!$B$7,1,0) -> 0 | D13: =C13*IF(A13=0,0,Inputs!$B$19) -> 0 | E13: =C13*IF(A13<1,0,IF(A13<=Inputs!$B$12,0,IF(A13-1<Inputs!$B$12,A13-Inputs!$B$12,1)*Inputs!$B$33*(1+Inputs!$B$14)^(5*INT((A13-1)/5)))) -> 0 | F13: =C13*(IF(A13=0,IF(Inputs!$B$24=0,Inputs!$B$39,0),0)+IF(AND(Inputs!$B$24>0,A13=Inputs!$B$24),Inputs!$B$39,0)) -> 0 | G13: =-C13*(IF(A13=0,Inputs!$B$38*(1+Inputs!$B$6)+Inputs!$B$36+Inputs!$B$20,0)+IF(A13=1,Inputs!$B$34+Inputs!$B$35,0)) -> 0 | H13: =-C13*IF(AND(Inputs!$B$24>0,A13>=1,A13<=Inputs!$B$24),Inputs!$B$25,0) -> 0 | I13: =IF(A13=Inputs!$B$7,Inputs!$B$43+Inputs!$B$44+Inputs!$B$40,0) -> 0 | J13: =SUM(D13:I13) -> 0 | K13: =-G13-F13 -> 0 | L13: =IF(A13=0,Inputs!$B$47,0) -> 0 | M13: =Q12 -> 0 | N13: =M13*Inputs!$B$29 -> 0 | O13: =L13*Inputs!$B$30 -> 0 | P13: =IF(K13<0,MIN(M13+L13,-K13),0)+IF(A13=Inputs!$B$7,M13+L13-IF(K13<0,MIN(M13+L13,-K13),0),0) -> 0 | Q13: =M13+L13-P13 -> 0 | R13: =L13-N13-P13-O13 -> 0 | S13: =J13+R13 -> 0 | T13: =T12+S13 -> 7969521.5
A14: 9 | B14: =IF(A14=0,"Completion",TEXT(2026+A14,"0")&IF(A14=Inputs!$B$7," and exit","")) -> 2035 | C14: =IF(A14<=Inputs!$B$7,1,0) -> 0 | D14: =C14*IF(A14=0,0,Inputs!$B$19) -> 0 | E14: =C14*IF(A14<1,0,IF(A14<=Inputs!$B$12,0,IF(A14-1<Inputs!$B$12,A14-Inputs!$B$12,1)*Inputs!$B$33*(1+Inputs!$B$14)^(5*INT((A14-1)/5)))) -> 0 | F14: =C14*(IF(A14=0,IF(Inputs!$B$24=0,Inputs!$B$39,0),0)+IF(AND(Inputs!$B$24>0,A14=Inputs!$B$24),Inputs!$B$39,0)) -> 0 | G14: =-C14*(IF(A14=0,Inputs!$B$38*(1+Inputs!$B$6)+Inputs!$B$36+Inputs!$B$20,0)+IF(A14=1,Inputs!$B$34+Inputs!$B$35,0)) -> 0 | H14: =-C14*IF(AND(Inputs!$B$24>0,A14>=1,A14<=Inputs!$B$24),Inputs!$B$25,0) -> 0 | I14: =IF(A14=Inputs!$B$7,Inputs!$B$43+Inputs!$B$44+Inputs!$B$40,0) -> 0 | J14: =SUM(D14:I14) -> 0 | K14: =-G14-F14 -> 0 | L14: =IF(A14=0,Inputs!$B$47,0) -> 0 | M14: =Q13 -> 0 | N14: =M14*Inputs!$B$29 -> 0 | O14: =L14*Inputs!$B$30 -> 0 | P14: =IF(K14<0,MIN(M14+L14,-K14),0)+IF(A14=Inputs!$B$7,M14+L14-IF(K14<0,MIN(M14+L14,-K14),0),0) -> 0 | Q14: =M14+L14-P14 -> 0 | R14: =L14-N14-P14-O14 -> 0 | S14: =J14+R14 -> 0 | T14: =T13+S14 -> 7969521.5
A15: 10 | B15: =IF(A15=0,"Completion",TEXT(2026+A15,"0")&IF(A15=Inputs!$B$7," and exit","")) -> 2036 | C15: =IF(A15<=Inputs!$B$7,1,0) -> 0 | D15: =C15*IF(A15=0,0,Inputs!$B$19) -> 0 | E15: =C15*IF(A15<1,0,IF(A15<=Inputs!$B$12,0,IF(A15-1<Inputs!$B$12,A15-Inputs!$B$12,1)*Inputs!$B$33*(1+Inputs!$B$14)^(5*INT((A15-1)/5)))) -> 0 | F15: =C15*(IF(A15=0,IF(Inputs!$B$24=0,Inputs!$B$39,0),0)+IF(AND(Inputs!$B$24>0,A15=Inputs!$B$24),Inputs!$B$39,0)) -> 0 | G15: =-C15*(IF(A15=0,Inputs!$B$38*(1+Inputs!$B$6)+Inputs!$B$36+Inputs!$B$20,0)+IF(A15=1,Inputs!$B$34+Inputs!$B$35,0)) -> 0 | H15: =-C15*IF(AND(Inputs!$B$24>0,A15>=1,A15<=Inputs!$B$24),Inputs!$B$25,0) -> 0 | I15: =IF(A15=Inputs!$B$7,Inputs!$B$43+Inputs!$B$44+Inputs!$B$40,0) -> 0 | J15: =SUM(D15:I15) -> 0 | K15: =-G15-F15 -> 0 | L15: =IF(A15=0,Inputs!$B$47,0) -> 0 | M15: =Q14 -> 0 | N15: =M15*Inputs!$B$29 -> 0 | O15: =L15*Inputs!$B$30 -> 0 | P15: =IF(K15<0,MIN(M15+L15,-K15),0)+IF(A15=Inputs!$B$7,M15+L15-IF(K15<0,MIN(M15+L15,-K15),0),0) -> 0 | Q15: =M15+L15-P15 -> 0 | R15: =L15-N15-P15-O15 -> 0 | S15: =J15+R15 -> 0 | T15: =T14+S15 -> 7969521.5
B16: Total | D16: =SUM(D5:D15) -> 300000 | E16: =SUM(E5:E15) -> 1804260 | F16: =SUM(F5:F15) -> 7000000 | G16: =SUM(G5:G15) -> -21028260 | H16: =SUM(H5:H15) -> 0 | I16: =SUM(I5:I15) -> 24362707 | J16: =SUM(J5:J15) -> 12438707 | K16: =SUM(K5:K15) -> 14028260 | ... S16: =SUM(S5:S15) -> 7969521.5

Sheet Outputs
A1: Outputs
A2: All figures recompute from Inputs. For the breakeven bid, Goal Seek Outputs!B13 to the target by changing the purchase price on Inputs; for the residential breakeven, change the Grange and cottages placeholder instead.
A4: Receipts
A5: Rent received during the hold | B5: ='Cash flow'!D16+'Cash flow'!E16 -> 2104260
A6: The Grange and cottages, exit valuation | B6: =Inputs!$B$39 -> 7000000
A7: Exit: Third Space, grounds and NTC reversion | B7: ='Cash flow'!I16 -> 24362707
A8: Total receipts | B8: =B5+B6+B7 -> 33466967
A9: Costs
A10: Purchase, works, incentives, premium and Grange holding | B10: =-'Cash flow'!G16-'Cash flow'!H16 -> 21028260
A11: Interest and fees | B11: ='Cash flow'!N16+'Cash flow'!O16 -> 4469185.8
A12: Total cost | B12: =B10+B11 -> 25497446
A13: Profit on cost | B13: =(B8-B12)/B12 -> 0.31256156
A14: Returns
A15: Profit | B15: =B8-B12 -> 7969521.5
A16: Profit on receipts | B16: =B15/B8 -> 0.23813097
A17: Yield on cost, stabilised rent over cost net of the residential value | B17: =(Inputs!$B$33+Inputs!$B$19)/(B10-Inputs!$B$39) -> 0.13574456
A18: Unlevered IRR | B18: =IRR('Cash flow'!J5:J15,-0.05) -> 0.16815715
A19: Levered IRR on equity | B19: =IRR('Cash flow'!S5:S15,-0.2) -> 0.29968218
A20: Equity multiple | B20: =SUMIF('Cash flow'!S5:S15,">0")/-SUMIF('Cash flow'!S5:S15,"<0") -> 1.9713278
A21: Peak equity | B21: =-MIN('Cash flow'!T5:T15) -> 8204770.3
A22: Peak debt | B22: =MAX('Cash flow'!Q5:Q15) -> 15681354
A23: Cash on cash, first full rent year if held | B23: =(Inputs!$B$33+Inputs!$B$19-B22*Inputs!$B$29)/B21 -> 0.06007946
A24: Debt on purchase, sized on the valuation after the lettings
A25: Valuation after the lettings | B25: =Inputs!$B$45 -> 31362707
A26: Loan drawn on completion | B26: =Inputs!$B$47 -> 15681354
A27: Loan to cost, implied | B27: =Inputs!$B$47/Inputs!$B$46 -> 0.74572759
A28: Equity on day one | B28: =Inputs!$B$46-Inputs!$B$47 -> 5346906.3
A29: Debt yield | B29: =(Inputs!$B$33+Inputs!$B$19)/Inputs!$B$47 -> 0.12143467
A30: Interest cover once rent is paying | B30: =(Inputs!$B$33+Inputs!$B$19)/(Inputs!$B$47*Inputs!$B$29) -> 1.3492741
A31: Interest shortfall during the rent-free | B31: =MAX(0,(Inputs!$B$47*Inputs!$B$29-Inputs!$B$19)*Inputs!$B$12) -> 2622643.7
